<?xml version="1.0"?>
<robot name="auto_robot">

  <link name="base_link"/>

  <joint name="body_link_joint" type="fixed">
    <parent link="base_link"/>
    <child link="body_link"/>
    <origin xyz="0 0 0.160"/>
  </joint>

  <link name="body_link">
    <visual>
      <geometry>
        <box size="0.630 0.360 0.200"/>
      </geometry>
    </visual>
    <collision>
      <geometry>
        <box size="0.630 0.360 0.200"/>
      </geometry>
    </collision>
    <inertial>
      <mass value="100.0"/>
      <inertia ixx="1.4133" ixy="0" ixz="0" iyy="3.6408" iyz="0" izz="4.3875"/>
    </inertial>
  </link>

  <link name="left_wheel_link">
    <visual>
      <geometry>
        <cylinder radius="0.13" length="0.08"/>
      </geometry>
    </visual>
    <collision>
      <geometry>
        <cylinder radius="0.13" length="0.08"/>
      </geometry>
    </collision>
    <inertial>
      <mass value="0.500"/>
      <inertia ixx="0.0013541667" ixy="0" ixz="0" iyy="0.0013541667" iyz="0" izz="0.0025"/>
    </inertial>
  </link>

  <joint name="left_wheel_joint" type="continuous">
    <parent link="body_link"/>
    <child link="left_wheel_link"/>
    <origin rpy="-1.5708 0 0" xyz="0.185 0.230 -0.030"/>
    <axis xyz="0 0 1"/>
  </joint>

  <link name="right_wheel_link">
    <visual>
      <geometry>
        <cylinder radius="0.13" length="0.08"/>
      </geometry>
    </visual>
    <collision>
      <geometry>
        <cylinder radius="0.13" length="0.08"/>
      </geometry>
    </collision>
    <inertial>
      <mass value="0.500"/>
      <inertia ixx="0.0013541667" ixy="0" ixz="0" iyy="0.0013541667" iyz="0" izz="0.0025"/>
    </inertial>
  </link>

  <joint name="right_wheel_joint" type="continuous">
    <parent link="body_link"/>
    <child link="right_wheel_link"/>
    <origin rpy="-1.5708 0 0" xyz="0.185 -0.230 -0.030"/>
    <axis xyz="0 0 1"/>
  </joint>

  <link name="caster_link">
    <visual>
      <geometry>
        <sphere radius="0.07"/>
      </geometry>
    </visual>
    <collision>
      <geometry>
        <sphere radius="0.07"/>
      </geometry>
    </collision>
    <inertial>
      <mass value="0.500"/>
      <inertia ixx="0.00025" ixy="0" ixz="0" iyy="0.00025"  iyz="0" izz="0.00025"/>
    </inertial>
  </link>
  
  <joint name="caster_joint" type="fixed">
    <parent link="body_link"/>
    <child link="caster_link"/>
    <origin xyz="-0.245 0 -0.090"/>
  </joint>

  <!-- LiDAR -->
  <link name="LiDAR_base_link">
    <visual>
      <geometry>
        <mesh filename="package://velodyne_description/meshes/VLP16_base_1.dae"/>
      </geometry>
    </visual>
    <visual>
      <geometry>
        <mesh filename="package://velodyne_description/meshes/VLP16_base_2.dae"/>
      </geometry>
    </visual>
    <collision>
      <origin rpy="0 0 0" xyz="0 0 0.03585"/>
      <geometry>
        <cylinder radius="0.0516" length="0.0717"/>
      </geometry>
    </collision>
    <inertial>
      <mass value="0.83"/>
      <origin xyz="0 0 0.03585"/>
      <inertia ixx="0.00091" ixy="0" ixz="0"
               iyy="0.00091" iyz="0" izz="0.001105"/>
    </inertial>
  </link>

  <joint name="LiDAR_base_mount_joint" type="fixed">
    <parent link="body_link"/>
    <child link="LiDAR_base_link"/>
    <origin xyz="0.2 0 0.1"/>
  </joint>

  <link name="LiDAR">
    <visual>
      <origin xyz="0 0 -0.0377"/>
      <geometry>
        <mesh filename="package://velodyne_description/meshes/VLP16_scan.dae"/>
      </geometry>
    </visual>
    <inertial>
      <mass value="0.01"/>
      <inertia ixx="1e-7" ixy="0" ixz="0" iyy="1e-7" iyz="0" izz="1e-7"/>
    </inertial>
  </link>

  <joint name="LiDAR_base_scan_joint" type="fixed">
    <origin xyz="0 0 0.0377"/>
    <parent link="LiDAR_base_link" />
    <child link="LiDAR"/>
  </joint>

  <!-- IMU -->
  <link name="imu_link"/>

  <joint name="imu_joint" type="fixed">
    <parent link="body_link"/>
    <child link="imu_link"/>
    <origin xyz="0.185 0 -0.030"/>
  </joint>

  <!-- Transmission -->
  <transmission name="left_wheel_trans">
    <type>transmission_interface/SimpleTransmission</type>
    <joint name="left_wheel_joint">
      <hardwareInterface>hardware_interface/VelocityJointInterface</hardwareInterface>
    </joint>
    <actuator name="left_wheel_motor">
      <hardwareInterface>hardware_interface/VelocityJointInterface</hardwareInterface>
      <mechanicalReduction>1</mechanicalReduction>
    </actuator>
  </transmission>

  <transmission name="right_wheel_trans">
    <type>transmission_interface/SimpleTransmission</type>
    <joint name="right_wheel_joint">
      <hardwareInterface>hardware_interface/VelocityJointInterface</hardwareInterface>
    </joint>
    <actuator name="right_wheel_motor">
      <hardwareInterface>hardware_interface/VelocityJointInterface</hardwareInterface>
      <mechanicalReduction>1</mechanicalReduction>
    </actuator>
  </transmission>

  <!-- Gazebo -->
  <gazebo>
    <plugin name="gazebo_ros_control" filename="libgazebo_ros_control.so"/>
  </gazebo>

  <gazebo reference="body_link">
    <selfCollide>true</selfCollide>
    <mu1 value="0.05"/>
    <mu2 value="0.05"/>
  </gazebo>

  <gazebo reference="left_wheel_link">
    <material>Gazebo/Green</material>
    <selfCollide>true</selfCollide>
    <mu1 value="0.8"/>
    <mu2 value="0.8"/>
  </gazebo>

  <gazebo reference="right_wheel_link">
    <material>Gazebo/Green</material>
    <selfCollide>true</selfCollide>
    <mu1 value="0.8"/>
    <mu2 value="0.8"/>
  </gazebo>

  <gazebo reference="caster_link">
  <material>Gazebo/Green</material>
    <selfCollide>true</selfCollide>
    <!-- This caster is no frictional resistance. -->
    <mu1 value="0.0"/>
    <mu2 value="0.0"/>
  </gazebo>

  <!-- 2D -->
  <gazebo reference="LiDAR">
    <sensor type="ray" name="LiDAR">
      <pose>0 0 0 0 0 0</pose>
      <visualize>false</visualize>
      <update_rate>10</update_rate>
      <ray>
        <scan>
          <horizontal>
            <samples>1875</samples>
            <resolution>1</resolution>
            <min_angle>-3.1416</min_angle>
            <max_angle>3.1416</max_angle>
          </horizontal>
        </scan>
        <range>
          <min>0.3</min>
          <max>131.0</max>
          <resolution>0.001</resolution>
        </range>
        <noise>
          <type>gaussian</type>
          <mean>0.0</mean>
          <stddev>0.0</stddev>
        </noise>
      </ray>
      <plugin name="gazebo_ros_laser_controller" filename="libgazebo_ros_laser.so">
        <topicName>scan</topicName>
        <frameName>LiDAR</frameName>
        <min_range>0.9</min_range>
        <max_range>130.0</max_range>
        <gaussianNoise>0.008</gaussianNoise>
      </plugin>
    </sensor>
  </gazebo>

  <!-- IMU  -->
  <gazebo reference="imu_link">
    <gravity>true</gravity>
    <sensor type="imu" name="IMU">
      <always_on>true</always_on>
      <update_rate>100</update_rate>
      <visualize>true</visualize>
      <topic>data</topic>
      <plugin filename="libgazebo_ros_imu_sensor.so" name="imu_plugin">
        <topicName>imu</topicName>
        <bodyName>imu_link</bodyName>
        <frameName>imu_link</frameName>
        <updateRateHZ>10.0</updateRateHZ>
        <gaussianNoise>0.0</gaussianNoise>
        <xyzOffset>0 0 0</xyzOffset>
        <rpyOffset>0 0 0</rpyOffset>
      </plugin>
    </sensor>
  </gazebo>

</robot>
