<?xml version="1.0"?>
<robot name="pmt_fcsc">

  <link name="base_link"/>

  <link name="base_floor">
    <visual>
      <geometry>
        <box size="0.400 0.280 0.050"/>
        <!-- <box size="0.500 0.380 0.050"/> -->
      </geometry>
      <material name="grey">
        <color rgba="0.5 0.5 0.5 1.0"/>
      </material>
    </visual>
  </link>

  <joint name="base_body_joint" type="fixed">
    <parent link="base_link"/>
    <child link="base_floor"/>
    <origin xyz="0.2 0 0" rpy="0 0 0"/>
  </joint>
<!-- 
  <link name="footrest_link">
    <visual>
      <geometry>
        <box size="0.250 0.260 0.050"/>
      </geometry>
      <material name="grey">
        <color rgba="0.5 0.5 0.5 1.0"/>
      </material>
    </visual>
  </link>

  <joint name="footrest_joint" type="fixed">
    <parent link="base_floor"/>
    <child link="footrest_link"/>
    <origin xyz="0.320 0 0" rpy="0 0 0"/>
  </joint> -->

  <link name="left_wheel_link">
    <visual>
      <geometry>
        <cylinder length="0.05" radius="0.075"/>
      </geometry>
      <material name="grey"/>
    </visual>
  </link>

  <joint name="leftWheel" type="continuous">
      <!-- <joint name="leftWheel" type="fixed"> -->
    <parent link="base_floor"/>
    <child link="left_wheel_link"/>
    <origin xyz="-0.2 0.14 0" rpy="-1.57079632679 0 0"/>
    <axis xyz="0 0 1"/>
  </joint>

  <link name="right_wheel_link">
    <visual>
      <geometry>
        <cylinder length="0.05" radius="0.075"/>
      </geometry>
      <material name="grey"/>
    </visual>
  </link>

  <joint name="rightWheel" type="continuous">
  <!-- <joint name="rightWheel" type="fixed"> -->
    <parent link="base_floor"/>
    <child link="right_wheel_link"/>
    <origin xyz="-0.2 -0.14 0" rpy="1.57079632679 0 0"/>
    <axis xyz="0 0 1"/>
  </joint>

  <link name="frontwheel_left">
    <visual>
      <geometry>
        <cylinder length="0.05" radius="0.075"/>
      </geometry>
      <material name="grey"/>
    </visual>
  </link>

  <joint name="frontwheel_left_joint" type="fixed">
    <parent link="base_floor"/>
    <child link="frontwheel_left"/>
    <origin xyz="0.2 0.14 0" rpy="-1.57079632679 0 0"/>
  </joint>

  <link name="frontwheel_right">
    <visual>
      <geometry>
        <cylinder length="0.05" radius="0.075"/>
      </geometry>
      <material name="grey"/>
    </visual>  
  </link>

  <joint name="frontwheel_right_joint" type="fixed">
    <parent link="base_floor"/>
    <child link="frontwheel_right"/>
    <origin xyz="0.2 -0.14 0" rpy="1.57079632679 0 0"/>
  </joint>

  <!-- VLP-16 -->
  <link name="velodyne_base_link">
    <visual>
      <geometry>
        <mesh filename="package://velodyne_description/meshes/VLP16_base_1.dae"/>
      </geometry>
    </visual>
    <visual>
      <geometry>
        <mesh filename="package://velodyne_description/meshes/VLP16_base_2.dae"/>
      </geometry>
    </visual>
    <collision>
      <origin rpy="0 0 0" xyz="0 0 0.03585"/>
      <geometry>
        <cylinder radius="0.0516" length="0.0717"/>
      </geometry>
    </collision>
    <inertial>
      <mass value="0.83"/>
      <origin xyz="0 0 0.03585"/>
      <inertia ixx="0.00091" ixy="0" ixz="0" iyy="0.00091" iyz="0" izz="0.001105"/>
    </inertial>
  </link>

  <joint name="velodyne_base_mount_joint" type="fixed">
    <parent link="base_link"/>
    <child link="velodyne_base_link"/>
    <!--<origin xyz="0.85 0 0.2298"/>-->
    <origin xyz="0.3 0.0 0.071"/>
  </joint>

  <link name="velodyne">
    <visual>
      <origin xyz="0 0 -0.0377"/>
      <geometry>
        <mesh filename="package://velodyne_description/meshes/VLP16_scan.dae"/>
      </geometry>
    </visual>
    <inertial>
      <mass value="0.01"/>
      <inertia ixx="1e-7" ixy="0" ixz="0" iyy="1e-7" iyz="0" izz="1e-7"/>
    </inertial>
  </link>

  <joint name="velodyne_base_scan_joint" type="fixed">
    <parent link="velodyne_base_link"/>
    <child link="velodyne"/>
    <origin xyz="0 0 0.0377"/>
  </joint>

</robot>
