<?xml version="1.0" ?>
<!-- =================================================================================== -->
<!-- |    This document was autogenerated by xacro from vmecanumrover.xacro            | -->
<!-- |    EDITING THIS FILE BY HAND IS NOT RECOMMENDED                                 | -->
<!-- =================================================================================== -->
<robot name="vmecanumrover">
  <link name="base_link"/>
  <joint name="body_joint" type="fixed">
    <parent link="base_link"/>
    <child link="body_link"/>
    <origin rpy="0 0 0" xyz="0 0 0.0"/>
  </joint>
  <link name="body_link">
    <visual>
      <geometry>
        <mesh filename="package://mecanumrover_samples/meshes/dae/mecanum_body.dae"/>
      </geometry>
      <material name="gray"/>
    </visual>
    <collision>
      <geometry>
        <mesh filename="package://mecanumrover_samples/meshes/stl/mecanum_body.stl"/>
      </geometry>
    </collision>
    <inertial>
      <mass value="14.004"/>
      <inertia ixx="0.22639800000000002" ixy="0" ixz="0" iyy="0.15617377500000004" iyz="0" izz="0.11276137500000001"/>
    </inertial>
  </link>
  <gazebo reference="body_link">
    <material>Gazebo/White</material>
  </gazebo>
  <joint name="wheel0_attach_joint" type="fixed">
    <parent link="base_link"/>
    <child link="wheel0_attach_link"/>
    <origin rpy="0 0 1.5707963267948966" xyz="0.115 0.132 0.075"/>
  </joint>
  <link name="wheel0_attach_link"/>
  <joint name="wheel0_base_joint" type="fixed">
    <parent link="wheel0_attach_link"/>
    <child link="wheel0_base_link"/>
    <origin rpy="0 0 0" xyz="0 0 0"/>
  </joint>
  <link name="wheel0_base_link">
    <inertial>
      <mass value="0.010"/>
      <inertia ixx="0.0001" ixy="0" ixz="0" iyy="0.0001" iyz="0" izz="0.0001"/>
    </inertial>
  </link>
  <joint name="wheel0_sus_joint" type="prismatic">
    <parent link="wheel0_base_link"/>
    <child link="wheel0_sus_link"/>
    <limit effort="100" lower="-0.02" upper="0.02" velocity="1.0"/>
    <axis xyz="0 0 1"/>
    <origin rpy="0 0 0" xyz="0 0 0"/>
    <dynamics damping="0.01"/>
  </joint>
  <transmission name="wheel0_sus_trans">
    <type>transmission_interface/SimpleTransmission</type>
    <joint name="wheel0_sus_joint">
      <hardwareInterface>hardware_interface/EffortJointInterface</hardwareInterface>
    </joint>
    <actuator name="wheel0_sus_motor">
      <hardwareInterface>hardware_interface/EffortJointInterface</hardwareInterface>
      <mechanismReduction>1</mechanismReduction>
    </actuator>
  </transmission>
  <gazebo reference="wheel0_sus_joint">
    <kp>50000</kp>
    <kd>500</kd>
  </gazebo>
  <link name="wheel0_sus_link">
    <inertial>
      <mass value="0.010"/>
      <inertia ixx="0.00001" ixy="0.0" ixz="0.0" iyy="0.00001" iyz="0.0" izz="0.00001"/>
    </inertial>
  </link>
  <joint name="wheel0_motor_joint" type="fixed">
    <parent link="wheel0_sus_link"/>
    <child link="wheel0_motor_body_link"/>
  </joint>
  <link name="wheel0_motor_body_link">
    <visual>
      <origin rpy="0 1.5707963267948966 0" xyz="-0.06075 0 0"/>
      <geometry>
        <cylinder length="0.1215" radius="0.02225"/>
      </geometry>
      <material name="gray"/>
    </visual>
    <collision>
      <origin rpy="0 1.5707963267948966 0" xyz="-0.06075 0 0"/>
      <geometry>
        <cylinder length="0.1215" radius="0.02225"/>
      </geometry>
    </collision>
    <inertial>
      <mass value="0.88"/>
      <inertia ixx="0.00119147875" ixy="0" ixz="0" iyy="0.00119147875" iyz="0" izz="0.00021782749999999998"/>
    </inertial>
  </link>
  <gazebo reference="wheel0_motor_body_link">
    <material>Gazebo/Gray</material>
  </gazebo>
  <joint name="wheel0_motor_shaft_joint" type="continuous">
    <parent link="wheel0_motor_body_link"/>
    <child link="wheel0_motor_shaft_link"/>
    <origin rpy="0 1.5707963267948966 0" xyz="0 0 0"/>
    <axis xyz="0 0 -1"/>
    <!-- <limit velocity="40.0" effort="3.0" /> -->
    <dynamics damping="0.01" friction="0.0"/>
  </joint>
  <transmission name="wheel0_motor_shaft_trans">
    <type>transmission_interface/SimpleTransmission</type>
    <joint name="wheel0_motor_shaft_joint">
      <hardwareInterface>hardware_interface/EffortJointInterface</hardwareInterface>
    </joint>
    <actuator name="wheel0_motor_shaft_motor">
      <hardwareInterface>hardware_interface/EffortJointInterface</hardwareInterface>
      <mechanicalReduction>1</mechanicalReduction>
    </actuator>
  </transmission>
  <link name="wheel0_motor_shaft_link">
    <visual>
      <geometry>
        <mesh filename="package://mecanumrover_samples/meshes/dae/mecanum_wheel_rev.dae"/>
      </geometry>
      <material name="gray"/>
    </visual>
    <collision>
      <origin rpy="0 0 0" xyz="0 0 0"/>
      <geometry>
        <!-- <cylinder radius="0.048" length="0.04572" /> -->
        <cylinder length="0.04572" radius="0.070"/>
        <!-- <mesh filename="package://mecanumrover_samples/meshes/stl/${mesh}.stl" />  -->
      </geometry>
    </collision>
    <inertial>
      <mass value="0.43525"/>
      <inertia ixx="0.0003265215903" ixy="0" ixz="0" iyy="0.0003265215903" iyz="0" izz="0.0005014080000000001"/>
    </inertial>
  </link>
  <gazebo reference="wheel0_motor_shaft_link">
    <material>Gazebo/White</material>
    <mu1 value="0.0"/>
    <mu2 value="0.0"/>
  </gazebo>
  <joint name="wheel0_barrel0_joint" type="continuous">
    <parent link="wheel0_motor_shaft_link"/>
    <child link="wheel0_barrel0_link"/>
    <origin rpy="-0.7853981633974483 0 0.0" xyz="0.0666389 0.0 0"/>
    <axis xyz="0 0 1"/>
    <dynamics damping="0.001" friction="0.0"/>
  </joint>
  <link name="wheel0_barrel0_link">
    <visual>
      <geometry>
        <mesh filename="package://mecanumrover_samples/meshes/dae/mecanum_barrel.dae"/>
      </geometry>
      <material name="black"/>
    </visual>
    <collision>
      <geometry>
        <cylinder length="0.0381" radius="0.00956"/>
      </geometry>
    </collision>
    <inertial>
      <mass value="0.01225"/>
      <inertia ixx="1.7617447750000001e-06" ixy="0" ixz="0" iyy="1.7617447750000001e-06" iyz="0" izz="5.597858000000001e-07"/>
    </inertial>
  </link>
  <gazebo reference="wheel0_barrel0_link">
    <material>Gazebo/Black</material>
    <mu1 value="2.5"/>
    <mu2 value="2.5"/>
    <kp value="50000"/>
    <kd value="100"/>
  </gazebo>
  <joint name="wheel0_barrel1_joint" type="continuous">
    <parent link="wheel0_motor_shaft_link"/>
    <child link="wheel0_barrel1_link"/>
    <origin rpy="-0.7853981633974483 0 0.4188790204786391" xyz="0.06087766439729952 0.027104482484263944 0"/>
    <axis xyz="0 0 1"/>
    <dynamics damping="0.001" friction="0.0"/>
  </joint>
  <link name="wheel0_barrel1_link">
    <visual>
      <geometry>
        <mesh filename="package://mecanumrover_samples/meshes/dae/mecanum_barrel.dae"/>
      </geometry>
      <material name="black"/>
    </visual>
    <collision>
      <geometry>
        <cylinder length="0.0381" radius="0.00956"/>
      </geometry>
    </collision>
    <inertial>
      <mass value="0.01225"/>
      <inertia ixx="1.7617447750000001e-06" ixy="0" ixz="0" iyy="1.7617447750000001e-06" iyz="0" izz="5.597858000000001e-07"/>
    </inertial>
  </link>
  <gazebo reference="wheel0_barrel1_link">
    <material>Gazebo/Black</material>
    <mu1 value="2.5"/>
    <mu2 value="2.5"/>
    <kp value="50000"/>
    <kd value="100"/>
  </gazebo>
  <joint name="wheel0_barrel2_joint" type="continuous">
    <parent link="wheel0_motor_shaft_link"/>
    <child link="wheel0_barrel2_link"/>
    <origin rpy="-0.7853981633974483 0 0.8377580409572782" xyz="0.04459012756408732 0.04952235371050553 0"/>
    <axis xyz="0 0 1"/>
    <dynamics damping="0.001" friction="0.0"/>
  </joint>
  <link name="wheel0_barrel2_link">
    <visual>
      <geometry>
        <mesh filename="package://mecanumrover_samples/meshes/dae/mecanum_barrel.dae"/>
      </geometry>
      <material name="black"/>
    </visual>
    <collision>
      <geometry>
        <cylinder length="0.0381" radius="0.00956"/>
      </geometry>
    </collision>
    <inertial>
      <mass value="0.01225"/>
      <inertia ixx="1.7617447750000001e-06" ixy="0" ixz="0" iyy="1.7617447750000001e-06" iyz="0" izz="5.597858000000001e-07"/>
    </inertial>
  </link>
  <gazebo reference="wheel0_barrel2_link">
    <material>Gazebo/Black</material>
    <mu1 value="2.5"/>
    <mu2 value="2.5"/>
    <kp value="50000"/>
    <kd value="100"/>
  </gazebo>
  <joint name="wheel0_barrel3_joint" type="continuous">
    <parent link="wheel0_motor_shaft_link"/>
    <child link="wheel0_barrel3_link"/>
    <origin rpy="-0.7853981633974483 0 1.2566370614359172" xyz="0.020592552586452685 0.0633773600837411 0"/>
    <axis xyz="0 0 1"/>
    <dynamics damping="0.001" friction="0.0"/>
  </joint>
  <link name="wheel0_barrel3_link">
    <visual>
      <geometry>
        <mesh filename="package://mecanumrover_samples/meshes/dae/mecanum_barrel.dae"/>
      </geometry>
      <material name="black"/>
    </visual>
    <collision>
      <geometry>
        <cylinder length="0.0381" radius="0.00956"/>
      </geometry>
    </collision>
    <inertial>
      <mass value="0.01225"/>
      <inertia ixx="1.7617447750000001e-06" ixy="0" ixz="0" iyy="1.7617447750000001e-06" iyz="0" izz="5.597858000000001e-07"/>
    </inertial>
  </link>
  <gazebo reference="wheel0_barrel3_link">
    <material>Gazebo/Black</material>
    <mu1 value="2.5"/>
    <mu2 value="2.5"/>
    <kp value="50000"/>
    <kd value="100"/>
  </gazebo>
  <joint name="wheel0_barrel4_joint" type="continuous">
    <parent link="wheel0_motor_shaft_link"/>
    <child link="wheel0_barrel4_link"/>
    <origin rpy="-0.7853981633974483 0 1.6755160819145565" xyz="-0.006965661810846838 0.06627384513325683 0"/>
    <axis xyz="0 0 1"/>
    <dynamics damping="0.001" friction="0.0"/>
  </joint>
  <link name="wheel0_barrel4_link">
    <visual>
      <geometry>
        <mesh filename="package://mecanumrover_samples/meshes/dae/mecanum_barrel.dae"/>
      </geometry>
      <material name="black"/>
    </visual>
    <collision>
      <geometry>
        <cylinder length="0.0381" radius="0.00956"/>
      </geometry>
    </collision>
    <inertial>
      <mass value="0.01225"/>
      <inertia ixx="1.7617447750000001e-06" ixy="0" ixz="0" iyy="1.7617447750000001e-06" iyz="0" izz="5.597858000000001e-07"/>
    </inertial>
  </link>
  <gazebo reference="wheel0_barrel4_link">
    <material>Gazebo/Black</material>
    <mu1 value="2.5"/>
    <mu2 value="2.5"/>
    <kp value="50000"/>
    <kd value="100"/>
  </gazebo>
  <joint name="wheel0_barrel5_joint" type="continuous">
    <parent link="wheel0_motor_shaft_link"/>
    <child link="wheel0_barrel5_link"/>
    <origin rpy="-0.7853981633974483 0 2.0943951023931953" xyz="-0.03331944999999999 0.05771098028025083 0"/>
    <axis xyz="0 0 1"/>
    <dynamics damping="0.001" friction="0.0"/>
  </joint>
  <link name="wheel0_barrel5_link">
    <visual>
      <geometry>
        <mesh filename="package://mecanumrover_samples/meshes/dae/mecanum_barrel.dae"/>
      </geometry>
      <material name="black"/>
    </visual>
    <collision>
      <geometry>
        <cylinder length="0.0381" radius="0.00956"/>
      </geometry>
    </collision>
    <inertial>
      <mass value="0.01225"/>
      <inertia ixx="1.7617447750000001e-06" ixy="0" ixz="0" iyy="1.7617447750000001e-06" iyz="0" izz="5.597858000000001e-07"/>
    </inertial>
  </link>
  <gazebo reference="wheel0_barrel5_link">
    <material>Gazebo/Black</material>
    <mu1 value="2.5"/>
    <mu2 value="2.5"/>
    <kp value="50000"/>
    <kd value="100"/>
  </gazebo>
  <joint name="wheel0_barrel6_joint" type="continuous">
    <parent link="wheel0_motor_shaft_link"/>
    <child link="wheel0_barrel6_link"/>
    <origin rpy="-0.7853981633974483 0 2.5132741228718345" xyz="-0.05391200258645268 0.03916936264899289 0"/>
    <axis xyz="0 0 1"/>
    <dynamics damping="0.001" friction="0.0"/>
  </joint>
  <link name="wheel0_barrel6_link">
    <visual>
      <geometry>
        <mesh filename="package://mecanumrover_samples/meshes/dae/mecanum_barrel.dae"/>
      </geometry>
      <material name="black"/>
    </visual>
    <collision>
      <geometry>
        <cylinder length="0.0381" radius="0.00956"/>
      </geometry>
    </collision>
    <inertial>
      <mass value="0.01225"/>
      <inertia ixx="1.7617447750000001e-06" ixy="0" ixz="0" iyy="1.7617447750000001e-06" iyz="0" izz="5.597858000000001e-07"/>
    </inertial>
  </link>
  <gazebo reference="wheel0_barrel6_link">
    <material>Gazebo/Black</material>
    <mu1 value="2.5"/>
    <mu2 value="2.5"/>
    <kp value="50000"/>
    <kd value="100"/>
  </gazebo>
  <joint name="wheel0_barrel7_joint" type="continuous">
    <parent link="wheel0_motor_shaft_link"/>
    <child link="wheel0_barrel7_link"/>
    <origin rpy="-0.7853981633974483 0 2.9321531433504737" xyz="-0.06518268015054 0.013855006373235581 0"/>
    <axis xyz="0 0 1"/>
    <dynamics damping="0.001" friction="0.0"/>
  </joint>
  <link name="wheel0_barrel7_link">
    <visual>
      <geometry>
        <mesh filename="package://mecanumrover_samples/meshes/dae/mecanum_barrel.dae"/>
      </geometry>
      <material name="black"/>
    </visual>
    <collision>
      <geometry>
        <cylinder length="0.0381" radius="0.00956"/>
      </geometry>
    </collision>
    <inertial>
      <mass value="0.01225"/>
      <inertia ixx="1.7617447750000001e-06" ixy="0" ixz="0" iyy="1.7617447750000001e-06" iyz="0" izz="5.597858000000001e-07"/>
    </inertial>
  </link>
  <gazebo reference="wheel0_barrel7_link">
    <material>Gazebo/Black</material>
    <mu1 value="2.5"/>
    <mu2 value="2.5"/>
    <kp value="50000"/>
    <kd value="100"/>
  </gazebo>
  <joint name="wheel0_barrel8_joint" type="continuous">
    <parent link="wheel0_motor_shaft_link"/>
    <child link="wheel0_barrel8_link"/>
    <origin rpy="-0.7853981633974483 0 3.351032163829113" xyz="-0.06518268015054 -0.013855006373235595 0"/>
    <axis xyz="0 0 1"/>
    <dynamics damping="0.001" friction="0.0"/>
  </joint>
  <link name="wheel0_barrel8_link">
    <visual>
      <geometry>
        <mesh filename="package://mecanumrover_samples/meshes/dae/mecanum_barrel.dae"/>
      </geometry>
      <material name="black"/>
    </visual>
    <collision>
      <geometry>
        <cylinder length="0.0381" radius="0.00956"/>
      </geometry>
    </collision>
    <inertial>
      <mass value="0.01225"/>
      <inertia ixx="1.7617447750000001e-06" ixy="0" ixz="0" iyy="1.7617447750000001e-06" iyz="0" izz="5.597858000000001e-07"/>
    </inertial>
  </link>
  <gazebo reference="wheel0_barrel8_link">
    <material>Gazebo/Black</material>
    <mu1 value="2.5"/>
    <mu2 value="2.5"/>
    <kp value="50000"/>
    <kd value="100"/>
  </gazebo>
  <joint name="wheel0_barrel9_joint" type="continuous">
    <parent link="wheel0_motor_shaft_link"/>
    <child link="wheel0_barrel9_link"/>
    <origin rpy="-0.7853981633974483 0 3.7699111843077517" xyz="-0.05391200258645269 -0.03916936264899288 0"/>
    <axis xyz="0 0 1"/>
    <dynamics damping="0.001" friction="0.0"/>
  </joint>
  <link name="wheel0_barrel9_link">
    <visual>
      <geometry>
        <mesh filename="package://mecanumrover_samples/meshes/dae/mecanum_barrel.dae"/>
      </geometry>
      <material name="black"/>
    </visual>
    <collision>
      <geometry>
        <cylinder length="0.0381" radius="0.00956"/>
      </geometry>
    </collision>
    <inertial>
      <mass value="0.01225"/>
      <inertia ixx="1.7617447750000001e-06" ixy="0" ixz="0" iyy="1.7617447750000001e-06" iyz="0" izz="5.597858000000001e-07"/>
    </inertial>
  </link>
  <gazebo reference="wheel0_barrel9_link">
    <material>Gazebo/Black</material>
    <mu1 value="2.5"/>
    <mu2 value="2.5"/>
    <kp value="50000"/>
    <kd value="100"/>
  </gazebo>
  <joint name="wheel0_barrel10_joint" type="continuous">
    <parent link="wheel0_motor_shaft_link"/>
    <child link="wheel0_barrel10_link"/>
    <origin rpy="-0.7853981633974483 0 4.1887902047863905" xyz="-0.03331945000000003 -0.05771098028025081 0"/>
    <axis xyz="0 0 1"/>
    <dynamics damping="0.001" friction="0.0"/>
  </joint>
  <link name="wheel0_barrel10_link">
    <visual>
      <geometry>
        <mesh filename="package://mecanumrover_samples/meshes/dae/mecanum_barrel.dae"/>
      </geometry>
      <material name="black"/>
    </visual>
    <collision>
      <geometry>
        <cylinder length="0.0381" radius="0.00956"/>
      </geometry>
    </collision>
    <inertial>
      <mass value="0.01225"/>
      <inertia ixx="1.7617447750000001e-06" ixy="0" ixz="0" iyy="1.7617447750000001e-06" iyz="0" izz="5.597858000000001e-07"/>
    </inertial>
  </link>
  <gazebo reference="wheel0_barrel10_link">
    <material>Gazebo/Black</material>
    <mu1 value="2.5"/>
    <mu2 value="2.5"/>
    <kp value="50000"/>
    <kd value="100"/>
  </gazebo>
  <joint name="wheel0_barrel11_joint" type="continuous">
    <parent link="wheel0_motor_shaft_link"/>
    <child link="wheel0_barrel11_link"/>
    <origin rpy="-0.7853981633974483 0 4.60766922526503" xyz="-0.006965661810846825 -0.06627384513325683 0"/>
    <axis xyz="0 0 1"/>
    <dynamics damping="0.001" friction="0.0"/>
  </joint>
  <link name="wheel0_barrel11_link">
    <visual>
      <geometry>
        <mesh filename="package://mecanumrover_samples/meshes/dae/mecanum_barrel.dae"/>
      </geometry>
      <material name="black"/>
    </visual>
    <collision>
      <geometry>
        <cylinder length="0.0381" radius="0.00956"/>
      </geometry>
    </collision>
    <inertial>
      <mass value="0.01225"/>
      <inertia ixx="1.7617447750000001e-06" ixy="0" ixz="0" iyy="1.7617447750000001e-06" iyz="0" izz="5.597858000000001e-07"/>
    </inertial>
  </link>
  <gazebo reference="wheel0_barrel11_link">
    <material>Gazebo/Black</material>
    <mu1 value="2.5"/>
    <mu2 value="2.5"/>
    <kp value="50000"/>
    <kd value="100"/>
  </gazebo>
  <joint name="wheel0_barrel12_joint" type="continuous">
    <parent link="wheel0_motor_shaft_link"/>
    <child link="wheel0_barrel12_link"/>
    <origin rpy="-0.7853981633974483 0 5.026548245743669" xyz="0.02059255258645267 -0.06337736008374112 0"/>
    <axis xyz="0 0 1"/>
    <dynamics damping="0.001" friction="0.0"/>
  </joint>
  <link name="wheel0_barrel12_link">
    <visual>
      <geometry>
        <mesh filename="package://mecanumrover_samples/meshes/dae/mecanum_barrel.dae"/>
      </geometry>
      <material name="black"/>
    </visual>
    <collision>
      <geometry>
        <cylinder length="0.0381" radius="0.00956"/>
      </geometry>
    </collision>
    <inertial>
      <mass value="0.01225"/>
      <inertia ixx="1.7617447750000001e-06" ixy="0" ixz="0" iyy="1.7617447750000001e-06" iyz="0" izz="5.597858000000001e-07"/>
    </inertial>
  </link>
  <gazebo reference="wheel0_barrel12_link">
    <material>Gazebo/Black</material>
    <mu1 value="2.5"/>
    <mu2 value="2.5"/>
    <kp value="50000"/>
    <kd value="100"/>
  </gazebo>
  <joint name="wheel0_barrel13_joint" type="continuous">
    <parent link="wheel0_motor_shaft_link"/>
    <child link="wheel0_barrel13_link"/>
    <origin rpy="-0.7853981633974483 0 5.445427266222308" xyz="0.04459012756408729 -0.04952235371050555 0"/>
    <axis xyz="0 0 1"/>
    <dynamics damping="0.001" friction="0.0"/>
  </joint>
  <link name="wheel0_barrel13_link">
    <visual>
      <geometry>
        <mesh filename="package://mecanumrover_samples/meshes/dae/mecanum_barrel.dae"/>
      </geometry>
      <material name="black"/>
    </visual>
    <collision>
      <geometry>
        <cylinder length="0.0381" radius="0.00956"/>
      </geometry>
    </collision>
    <inertial>
      <mass value="0.01225"/>
      <inertia ixx="1.7617447750000001e-06" ixy="0" ixz="0" iyy="1.7617447750000001e-06" iyz="0" izz="5.597858000000001e-07"/>
    </inertial>
  </link>
  <gazebo reference="wheel0_barrel13_link">
    <material>Gazebo/Black</material>
    <mu1 value="2.5"/>
    <mu2 value="2.5"/>
    <kp value="50000"/>
    <kd value="100"/>
  </gazebo>
  <joint name="wheel0_barrel14_joint" type="continuous">
    <parent link="wheel0_motor_shaft_link"/>
    <child link="wheel0_barrel14_link"/>
    <origin rpy="-0.7853981633974483 0 5.8643062867009474" xyz="0.060877664397299525 -0.02710448248426394 0"/>
    <axis xyz="0 0 1"/>
    <dynamics damping="0.001" friction="0.0"/>
  </joint>
  <link name="wheel0_barrel14_link">
    <visual>
      <geometry>
        <mesh filename="package://mecanumrover_samples/meshes/dae/mecanum_barrel.dae"/>
      </geometry>
      <material name="black"/>
    </visual>
    <collision>
      <geometry>
        <cylinder length="0.0381" radius="0.00956"/>
      </geometry>
    </collision>
    <inertial>
      <mass value="0.01225"/>
      <inertia ixx="1.7617447750000001e-06" ixy="0" ixz="0" iyy="1.7617447750000001e-06" iyz="0" izz="5.597858000000001e-07"/>
    </inertial>
  </link>
  <gazebo reference="wheel0_barrel14_link">
    <material>Gazebo/Black</material>
    <mu1 value="2.5"/>
    <mu2 value="2.5"/>
    <kp value="50000"/>
    <kd value="100"/>
  </gazebo>
  <joint name="wheel1_attach_joint" type="fixed">
    <parent link="base_link"/>
    <child link="wheel1_attach_link"/>
    <origin rpy="0 0 -1.5707963267948966" xyz="0.115 -0.132 0.075"/>
  </joint>
  <link name="wheel1_attach_link"/>
  <joint name="wheel1_base_joint" type="fixed">
    <parent link="wheel1_attach_link"/>
    <child link="wheel1_base_link"/>
    <origin rpy="0 0 0" xyz="0 0 0"/>
  </joint>
  <link name="wheel1_base_link">
    <inertial>
      <mass value="0.010"/>
      <inertia ixx="0.0001" ixy="0" ixz="0" iyy="0.0001" iyz="0" izz="0.0001"/>
    </inertial>
  </link>
  <joint name="wheel1_sus_joint" type="prismatic">
    <parent link="wheel1_base_link"/>
    <child link="wheel1_sus_link"/>
    <limit effort="100" lower="-0.02" upper="0.02" velocity="1.0"/>
    <axis xyz="0 0 1"/>
    <origin rpy="0 0 0" xyz="0 0 0"/>
    <dynamics damping="0.01"/>
  </joint>
  <transmission name="wheel1_sus_trans">
    <type>transmission_interface/SimpleTransmission</type>
    <joint name="wheel1_sus_joint">
      <hardwareInterface>hardware_interface/EffortJointInterface</hardwareInterface>
    </joint>
    <actuator name="wheel1_sus_motor">
      <hardwareInterface>hardware_interface/EffortJointInterface</hardwareInterface>
      <mechanismReduction>1</mechanismReduction>
    </actuator>
  </transmission>
  <gazebo reference="wheel1_sus_joint">
    <kp>50000</kp>
    <kd>500</kd>
  </gazebo>
  <link name="wheel1_sus_link">
    <inertial>
      <mass value="0.010"/>
      <inertia ixx="0.00001" ixy="0.0" ixz="0.0" iyy="0.00001" iyz="0.0" izz="0.00001"/>
    </inertial>
  </link>
  <joint name="wheel1_motor_joint" type="fixed">
    <parent link="wheel1_sus_link"/>
    <child link="wheel1_motor_body_link"/>
  </joint>
  <link name="wheel1_motor_body_link">
    <visual>
      <origin rpy="0 1.5707963267948966 0" xyz="-0.06075 0 0"/>
      <geometry>
        <cylinder length="0.1215" radius="0.02225"/>
      </geometry>
      <material name="gray"/>
    </visual>
    <collision>
      <origin rpy="0 1.5707963267948966 0" xyz="-0.06075 0 0"/>
      <geometry>
        <cylinder length="0.1215" radius="0.02225"/>
      </geometry>
    </collision>
    <inertial>
      <mass value="0.88"/>
      <inertia ixx="0.00119147875" ixy="0" ixz="0" iyy="0.00119147875" iyz="0" izz="0.00021782749999999998"/>
    </inertial>
  </link>
  <gazebo reference="wheel1_motor_body_link">
    <material>Gazebo/Gray</material>
  </gazebo>
  <joint name="wheel1_motor_shaft_joint" type="continuous">
    <parent link="wheel1_motor_body_link"/>
    <child link="wheel1_motor_shaft_link"/>
    <origin rpy="0 1.5707963267948966 0" xyz="0 0 0"/>
    <axis xyz="0 0 -1"/>
    <!-- <limit velocity="40.0" effort="3.0" /> -->
    <dynamics damping="0.01" friction="0.0"/>
  </joint>
  <transmission name="wheel1_motor_shaft_trans">
    <type>transmission_interface/SimpleTransmission</type>
    <joint name="wheel1_motor_shaft_joint">
      <hardwareInterface>hardware_interface/EffortJointInterface</hardwareInterface>
    </joint>
    <actuator name="wheel1_motor_shaft_motor">
      <hardwareInterface>hardware_interface/EffortJointInterface</hardwareInterface>
      <mechanicalReduction>1</mechanicalReduction>
    </actuator>
  </transmission>
  <link name="wheel1_motor_shaft_link">
    <visual>
      <geometry>
        <mesh filename="package://mecanumrover_samples/meshes/dae/mecanum_wheel.dae"/>
      </geometry>
      <material name="gray"/>
    </visual>
    <collision>
      <origin rpy="0 0 0" xyz="0 0 0"/>
      <geometry>
        <!-- <cylinder radius="0.048" length="0.04572" /> -->
        <cylinder length="0.04572" radius="0.070"/>
        <!-- <mesh filename="package://mecanumrover_samples/meshes/stl/${mesh}.stl" />  -->
      </geometry>
    </collision>
    <inertial>
      <mass value="0.43525"/>
      <inertia ixx="0.0003265215903" ixy="0" ixz="0" iyy="0.0003265215903" iyz="0" izz="0.0005014080000000001"/>
    </inertial>
  </link>
  <gazebo reference="wheel1_motor_shaft_link">
    <material>Gazebo/White</material>
    <mu1 value="0.0"/>
    <mu2 value="0.0"/>
  </gazebo>
  <joint name="wheel1_barrel0_joint" type="continuous">
    <parent link="wheel1_motor_shaft_link"/>
    <child link="wheel1_barrel0_link"/>
    <origin rpy="0.7853981633974483 0 0.0" xyz="0.0666389 0.0 0"/>
    <axis xyz="0 0 1"/>
    <dynamics damping="0.001" friction="0.0"/>
  </joint>
  <link name="wheel1_barrel0_link">
    <visual>
      <geometry>
        <mesh filename="package://mecanumrover_samples/meshes/dae/mecanum_barrel.dae"/>
      </geometry>
      <material name="black"/>
    </visual>
    <collision>
      <geometry>
        <cylinder length="0.0381" radius="0.00956"/>
      </geometry>
    </collision>
    <inertial>
      <mass value="0.01225"/>
      <inertia ixx="1.7617447750000001e-06" ixy="0" ixz="0" iyy="1.7617447750000001e-06" iyz="0" izz="5.597858000000001e-07"/>
    </inertial>
  </link>
  <gazebo reference="wheel1_barrel0_link">
    <material>Gazebo/Black</material>
    <mu1 value="2.5"/>
    <mu2 value="2.5"/>
    <kp value="50000"/>
    <kd value="100"/>
  </gazebo>
  <joint name="wheel1_barrel1_joint" type="continuous">
    <parent link="wheel1_motor_shaft_link"/>
    <child link="wheel1_barrel1_link"/>
    <origin rpy="0.7853981633974483 0 0.4188790204786391" xyz="0.06087766439729952 0.027104482484263944 0"/>
    <axis xyz="0 0 1"/>
    <dynamics damping="0.001" friction="0.0"/>
  </joint>
  <link name="wheel1_barrel1_link">
    <visual>
      <geometry>
        <mesh filename="package://mecanumrover_samples/meshes/dae/mecanum_barrel.dae"/>
      </geometry>
      <material name="black"/>
    </visual>
    <collision>
      <geometry>
        <cylinder length="0.0381" radius="0.00956"/>
      </geometry>
    </collision>
    <inertial>
      <mass value="0.01225"/>
      <inertia ixx="1.7617447750000001e-06" ixy="0" ixz="0" iyy="1.7617447750000001e-06" iyz="0" izz="5.597858000000001e-07"/>
    </inertial>
  </link>
  <gazebo reference="wheel1_barrel1_link">
    <material>Gazebo/Black</material>
    <mu1 value="2.5"/>
    <mu2 value="2.5"/>
    <kp value="50000"/>
    <kd value="100"/>
  </gazebo>
  <joint name="wheel1_barrel2_joint" type="continuous">
    <parent link="wheel1_motor_shaft_link"/>
    <child link="wheel1_barrel2_link"/>
    <origin rpy="0.7853981633974483 0 0.8377580409572782" xyz="0.04459012756408732 0.04952235371050553 0"/>
    <axis xyz="0 0 1"/>
    <dynamics damping="0.001" friction="0.0"/>
  </joint>
  <link name="wheel1_barrel2_link">
    <visual>
      <geometry>
        <mesh filename="package://mecanumrover_samples/meshes/dae/mecanum_barrel.dae"/>
      </geometry>
      <material name="black"/>
    </visual>
    <collision>
      <geometry>
        <cylinder length="0.0381" radius="0.00956"/>
      </geometry>
    </collision>
    <inertial>
      <mass value="0.01225"/>
      <inertia ixx="1.7617447750000001e-06" ixy="0" ixz="0" iyy="1.7617447750000001e-06" iyz="0" izz="5.597858000000001e-07"/>
    </inertial>
  </link>
  <gazebo reference="wheel1_barrel2_link">
    <material>Gazebo/Black</material>
    <mu1 value="2.5"/>
    <mu2 value="2.5"/>
    <kp value="50000"/>
    <kd value="100"/>
  </gazebo>
  <joint name="wheel1_barrel3_joint" type="continuous">
    <parent link="wheel1_motor_shaft_link"/>
    <child link="wheel1_barrel3_link"/>
    <origin rpy="0.7853981633974483 0 1.2566370614359172" xyz="0.020592552586452685 0.0633773600837411 0"/>
    <axis xyz="0 0 1"/>
    <dynamics damping="0.001" friction="0.0"/>
  </joint>
  <link name="wheel1_barrel3_link">
    <visual>
      <geometry>
        <mesh filename="package://mecanumrover_samples/meshes/dae/mecanum_barrel.dae"/>
      </geometry>
      <material name="black"/>
    </visual>
    <collision>
      <geometry>
        <cylinder length="0.0381" radius="0.00956"/>
      </geometry>
    </collision>
    <inertial>
      <mass value="0.01225"/>
      <inertia ixx="1.7617447750000001e-06" ixy="0" ixz="0" iyy="1.7617447750000001e-06" iyz="0" izz="5.597858000000001e-07"/>
    </inertial>
  </link>
  <gazebo reference="wheel1_barrel3_link">
    <material>Gazebo/Black</material>
    <mu1 value="2.5"/>
    <mu2 value="2.5"/>
    <kp value="50000"/>
    <kd value="100"/>
  </gazebo>
  <joint name="wheel1_barrel4_joint" type="continuous">
    <parent link="wheel1_motor_shaft_link"/>
    <child link="wheel1_barrel4_link"/>
    <origin rpy="0.7853981633974483 0 1.6755160819145565" xyz="-0.006965661810846838 0.06627384513325683 0"/>
    <axis xyz="0 0 1"/>
    <dynamics damping="0.001" friction="0.0"/>
  </joint>
  <link name="wheel1_barrel4_link">
    <visual>
      <geometry>
        <mesh filename="package://mecanumrover_samples/meshes/dae/mecanum_barrel.dae"/>
      </geometry>
      <material name="black"/>
    </visual>
    <collision>
      <geometry>
        <cylinder length="0.0381" radius="0.00956"/>
      </geometry>
    </collision>
    <inertial>
      <mass value="0.01225"/>
      <inertia ixx="1.7617447750000001e-06" ixy="0" ixz="0" iyy="1.7617447750000001e-06" iyz="0" izz="5.597858000000001e-07"/>
    </inertial>
  </link>
  <gazebo reference="wheel1_barrel4_link">
    <material>Gazebo/Black</material>
    <mu1 value="2.5"/>
    <mu2 value="2.5"/>
    <kp value="50000"/>
    <kd value="100"/>
  </gazebo>
  <joint name="wheel1_barrel5_joint" type="continuous">
    <parent link="wheel1_motor_shaft_link"/>
    <child link="wheel1_barrel5_link"/>
    <origin rpy="0.7853981633974483 0 2.0943951023931953" xyz="-0.03331944999999999 0.05771098028025083 0"/>
    <axis xyz="0 0 1"/>
    <dynamics damping="0.001" friction="0.0"/>
  </joint>
  <link name="wheel1_barrel5_link">
    <visual>
      <geometry>
        <mesh filename="package://mecanumrover_samples/meshes/dae/mecanum_barrel.dae"/>
      </geometry>
      <material name="black"/>
    </visual>
    <collision>
      <geometry>
        <cylinder length="0.0381" radius="0.00956"/>
      </geometry>
    </collision>
    <inertial>
      <mass value="0.01225"/>
      <inertia ixx="1.7617447750000001e-06" ixy="0" ixz="0" iyy="1.7617447750000001e-06" iyz="0" izz="5.597858000000001e-07"/>
    </inertial>
  </link>
  <gazebo reference="wheel1_barrel5_link">
    <material>Gazebo/Black</material>
    <mu1 value="2.5"/>
    <mu2 value="2.5"/>
    <kp value="50000"/>
    <kd value="100"/>
  </gazebo>
  <joint name="wheel1_barrel6_joint" type="continuous">
    <parent link="wheel1_motor_shaft_link"/>
    <child link="wheel1_barrel6_link"/>
    <origin rpy="0.7853981633974483 0 2.5132741228718345" xyz="-0.05391200258645268 0.03916936264899289 0"/>
    <axis xyz="0 0 1"/>
    <dynamics damping="0.001" friction="0.0"/>
  </joint>
  <link name="wheel1_barrel6_link">
    <visual>
      <geometry>
        <mesh filename="package://mecanumrover_samples/meshes/dae/mecanum_barrel.dae"/>
      </geometry>
      <material name="black"/>
    </visual>
    <collision>
      <geometry>
        <cylinder length="0.0381" radius="0.00956"/>
      </geometry>
    </collision>
    <inertial>
      <mass value="0.01225"/>
      <inertia ixx="1.7617447750000001e-06" ixy="0" ixz="0" iyy="1.7617447750000001e-06" iyz="0" izz="5.597858000000001e-07"/>
    </inertial>
  </link>
  <gazebo reference="wheel1_barrel6_link">
    <material>Gazebo/Black</material>
    <mu1 value="2.5"/>
    <mu2 value="2.5"/>
    <kp value="50000"/>
    <kd value="100"/>
  </gazebo>
  <joint name="wheel1_barrel7_joint" type="continuous">
    <parent link="wheel1_motor_shaft_link"/>
    <child link="wheel1_barrel7_link"/>
    <origin rpy="0.7853981633974483 0 2.9321531433504737" xyz="-0.06518268015054 0.013855006373235581 0"/>
    <axis xyz="0 0 1"/>
    <dynamics damping="0.001" friction="0.0"/>
  </joint>
  <link name="wheel1_barrel7_link">
    <visual>
      <geometry>
        <mesh filename="package://mecanumrover_samples/meshes/dae/mecanum_barrel.dae"/>
      </geometry>
      <material name="black"/>
    </visual>
    <collision>
      <geometry>
        <cylinder length="0.0381" radius="0.00956"/>
      </geometry>
    </collision>
    <inertial>
      <mass value="0.01225"/>
      <inertia ixx="1.7617447750000001e-06" ixy="0" ixz="0" iyy="1.7617447750000001e-06" iyz="0" izz="5.597858000000001e-07"/>
    </inertial>
  </link>
  <gazebo reference="wheel1_barrel7_link">
    <material>Gazebo/Black</material>
    <mu1 value="2.5"/>
    <mu2 value="2.5"/>
    <kp value="50000"/>
    <kd value="100"/>
  </gazebo>
  <joint name="wheel1_barrel8_joint" type="continuous">
    <parent link="wheel1_motor_shaft_link"/>
    <child link="wheel1_barrel8_link"/>
    <origin rpy="0.7853981633974483 0 3.351032163829113" xyz="-0.06518268015054 -0.013855006373235595 0"/>
    <axis xyz="0 0 1"/>
    <dynamics damping="0.001" friction="0.0"/>
  </joint>
  <link name="wheel1_barrel8_link">
    <visual>
      <geometry>
        <mesh filename="package://mecanumrover_samples/meshes/dae/mecanum_barrel.dae"/>
      </geometry>
      <material name="black"/>
    </visual>
    <collision>
      <geometry>
        <cylinder length="0.0381" radius="0.00956"/>
      </geometry>
    </collision>
    <inertial>
      <mass value="0.01225"/>
      <inertia ixx="1.7617447750000001e-06" ixy="0" ixz="0" iyy="1.7617447750000001e-06" iyz="0" izz="5.597858000000001e-07"/>
    </inertial>
  </link>
  <gazebo reference="wheel1_barrel8_link">
    <material>Gazebo/Black</material>
    <mu1 value="2.5"/>
    <mu2 value="2.5"/>
    <kp value="50000"/>
    <kd value="100"/>
  </gazebo>
  <joint name="wheel1_barrel9_joint" type="continuous">
    <parent link="wheel1_motor_shaft_link"/>
    <child link="wheel1_barrel9_link"/>
    <origin rpy="0.7853981633974483 0 3.7699111843077517" xyz="-0.05391200258645269 -0.03916936264899288 0"/>
    <axis xyz="0 0 1"/>
    <dynamics damping="0.001" friction="0.0"/>
  </joint>
  <link name="wheel1_barrel9_link">
    <visual>
      <geometry>
        <mesh filename="package://mecanumrover_samples/meshes/dae/mecanum_barrel.dae"/>
      </geometry>
      <material name="black"/>
    </visual>
    <collision>
      <geometry>
        <cylinder length="0.0381" radius="0.00956"/>
      </geometry>
    </collision>
    <inertial>
      <mass value="0.01225"/>
      <inertia ixx="1.7617447750000001e-06" ixy="0" ixz="0" iyy="1.7617447750000001e-06" iyz="0" izz="5.597858000000001e-07"/>
    </inertial>
  </link>
  <gazebo reference="wheel1_barrel9_link">
    <material>Gazebo/Black</material>
    <mu1 value="2.5"/>
    <mu2 value="2.5"/>
    <kp value="50000"/>
    <kd value="100"/>
  </gazebo>
  <joint name="wheel1_barrel10_joint" type="continuous">
    <parent link="wheel1_motor_shaft_link"/>
    <child link="wheel1_barrel10_link"/>
    <origin rpy="0.7853981633974483 0 4.1887902047863905" xyz="-0.03331945000000003 -0.05771098028025081 0"/>
    <axis xyz="0 0 1"/>
    <dynamics damping="0.001" friction="0.0"/>
  </joint>
  <link name="wheel1_barrel10_link">
    <visual>
      <geometry>
        <mesh filename="package://mecanumrover_samples/meshes/dae/mecanum_barrel.dae"/>
      </geometry>
      <material name="black"/>
    </visual>
    <collision>
      <geometry>
        <cylinder length="0.0381" radius="0.00956"/>
      </geometry>
    </collision>
    <inertial>
      <mass value="0.01225"/>
      <inertia ixx="1.7617447750000001e-06" ixy="0" ixz="0" iyy="1.7617447750000001e-06" iyz="0" izz="5.597858000000001e-07"/>
    </inertial>
  </link>
  <gazebo reference="wheel1_barrel10_link">
    <material>Gazebo/Black</material>
    <mu1 value="2.5"/>
    <mu2 value="2.5"/>
    <kp value="50000"/>
    <kd value="100"/>
  </gazebo>
  <joint name="wheel1_barrel11_joint" type="continuous">
    <parent link="wheel1_motor_shaft_link"/>
    <child link="wheel1_barrel11_link"/>
    <origin rpy="0.7853981633974483 0 4.60766922526503" xyz="-0.006965661810846825 -0.06627384513325683 0"/>
    <axis xyz="0 0 1"/>
    <dynamics damping="0.001" friction="0.0"/>
  </joint>
  <link name="wheel1_barrel11_link">
    <visual>
      <geometry>
        <mesh filename="package://mecanumrover_samples/meshes/dae/mecanum_barrel.dae"/>
      </geometry>
      <material name="black"/>
    </visual>
    <collision>
      <geometry>
        <cylinder length="0.0381" radius="0.00956"/>
      </geometry>
    </collision>
    <inertial>
      <mass value="0.01225"/>
      <inertia ixx="1.7617447750000001e-06" ixy="0" ixz="0" iyy="1.7617447750000001e-06" iyz="0" izz="5.597858000000001e-07"/>
    </inertial>
  </link>
  <gazebo reference="wheel1_barrel11_link">
    <material>Gazebo/Black</material>
    <mu1 value="2.5"/>
    <mu2 value="2.5"/>
    <kp value="50000"/>
    <kd value="100"/>
  </gazebo>
  <joint name="wheel1_barrel12_joint" type="continuous">
    <parent link="wheel1_motor_shaft_link"/>
    <child link="wheel1_barrel12_link"/>
    <origin rpy="0.7853981633974483 0 5.026548245743669" xyz="0.02059255258645267 -0.06337736008374112 0"/>
    <axis xyz="0 0 1"/>
    <dynamics damping="0.001" friction="0.0"/>
  </joint>
  <link name="wheel1_barrel12_link">
    <visual>
      <geometry>
        <mesh filename="package://mecanumrover_samples/meshes/dae/mecanum_barrel.dae"/>
      </geometry>
      <material name="black"/>
    </visual>
    <collision>
      <geometry>
        <cylinder length="0.0381" radius="0.00956"/>
      </geometry>
    </collision>
    <inertial>
      <mass value="0.01225"/>
      <inertia ixx="1.7617447750000001e-06" ixy="0" ixz="0" iyy="1.7617447750000001e-06" iyz="0" izz="5.597858000000001e-07"/>
    </inertial>
  </link>
  <gazebo reference="wheel1_barrel12_link">
    <material>Gazebo/Black</material>
    <mu1 value="2.5"/>
    <mu2 value="2.5"/>
    <kp value="50000"/>
    <kd value="100"/>
  </gazebo>
  <joint name="wheel1_barrel13_joint" type="continuous">
    <parent link="wheel1_motor_shaft_link"/>
    <child link="wheel1_barrel13_link"/>
    <origin rpy="0.7853981633974483 0 5.445427266222308" xyz="0.04459012756408729 -0.04952235371050555 0"/>
    <axis xyz="0 0 1"/>
    <dynamics damping="0.001" friction="0.0"/>
  </joint>
  <link name="wheel1_barrel13_link">
    <visual>
      <geometry>
        <mesh filename="package://mecanumrover_samples/meshes/dae/mecanum_barrel.dae"/>
      </geometry>
      <material name="black"/>
    </visual>
    <collision>
      <geometry>
        <cylinder length="0.0381" radius="0.00956"/>
      </geometry>
    </collision>
    <inertial>
      <mass value="0.01225"/>
      <inertia ixx="1.7617447750000001e-06" ixy="0" ixz="0" iyy="1.7617447750000001e-06" iyz="0" izz="5.597858000000001e-07"/>
    </inertial>
  </link>
  <gazebo reference="wheel1_barrel13_link">
    <material>Gazebo/Black</material>
    <mu1 value="2.5"/>
    <mu2 value="2.5"/>
    <kp value="50000"/>
    <kd value="100"/>
  </gazebo>
  <joint name="wheel1_barrel14_joint" type="continuous">
    <parent link="wheel1_motor_shaft_link"/>
    <child link="wheel1_barrel14_link"/>
    <origin rpy="0.7853981633974483 0 5.8643062867009474" xyz="0.060877664397299525 -0.02710448248426394 0"/>
    <axis xyz="0 0 1"/>
    <dynamics damping="0.001" friction="0.0"/>
  </joint>
  <link name="wheel1_barrel14_link">
    <visual>
      <geometry>
        <mesh filename="package://mecanumrover_samples/meshes/dae/mecanum_barrel.dae"/>
      </geometry>
      <material name="black"/>
    </visual>
    <collision>
      <geometry>
        <cylinder length="0.0381" radius="0.00956"/>
      </geometry>
    </collision>
    <inertial>
      <mass value="0.01225"/>
      <inertia ixx="1.7617447750000001e-06" ixy="0" ixz="0" iyy="1.7617447750000001e-06" iyz="0" izz="5.597858000000001e-07"/>
    </inertial>
  </link>
  <gazebo reference="wheel1_barrel14_link">
    <material>Gazebo/Black</material>
    <mu1 value="2.5"/>
    <mu2 value="2.5"/>
    <kp value="50000"/>
    <kd value="100"/>
  </gazebo>
  <joint name="wheel2_attach_joint" type="fixed">
    <parent link="base_link"/>
    <child link="wheel2_attach_link"/>
    <origin rpy="0 0 1.5707963267948966" xyz="-0.115 0.132 0.075"/>
  </joint>
  <link name="wheel2_attach_link"/>
  <joint name="wheel2_base_joint" type="fixed">
    <parent link="wheel2_attach_link"/>
    <child link="wheel2_base_link"/>
    <origin rpy="0 0 0" xyz="0 0 0"/>
  </joint>
  <link name="wheel2_base_link">
    <inertial>
      <mass value="0.010"/>
      <inertia ixx="0.0001" ixy="0" ixz="0" iyy="0.0001" iyz="0" izz="0.0001"/>
    </inertial>
  </link>
  <joint name="wheel2_sus_joint" type="prismatic">
    <parent link="wheel2_base_link"/>
    <child link="wheel2_sus_link"/>
    <limit effort="100" lower="-0.02" upper="0.02" velocity="1.0"/>
    <axis xyz="0 0 1"/>
    <origin rpy="0 0 0" xyz="0 0 0"/>
    <dynamics damping="0.01"/>
  </joint>
  <transmission name="wheel2_sus_trans">
    <type>transmission_interface/SimpleTransmission</type>
    <joint name="wheel2_sus_joint">
      <hardwareInterface>hardware_interface/EffortJointInterface</hardwareInterface>
    </joint>
    <actuator name="wheel2_sus_motor">
      <hardwareInterface>hardware_interface/EffortJointInterface</hardwareInterface>
      <mechanismReduction>1</mechanismReduction>
    </actuator>
  </transmission>
  <gazebo reference="wheel2_sus_joint">
    <kp>50000</kp>
    <kd>500</kd>
  </gazebo>
  <link name="wheel2_sus_link">
    <inertial>
      <mass value="0.010"/>
      <inertia ixx="0.00001" ixy="0.0" ixz="0.0" iyy="0.00001" iyz="0.0" izz="0.00001"/>
    </inertial>
  </link>
  <joint name="wheel2_motor_joint" type="fixed">
    <parent link="wheel2_sus_link"/>
    <child link="wheel2_motor_body_link"/>
  </joint>
  <link name="wheel2_motor_body_link">
    <visual>
      <origin rpy="0 1.5707963267948966 0" xyz="-0.06075 0 0"/>
      <geometry>
        <cylinder length="0.1215" radius="0.02225"/>
      </geometry>
      <material name="gray"/>
    </visual>
    <collision>
      <origin rpy="0 1.5707963267948966 0" xyz="-0.06075 0 0"/>
      <geometry>
        <cylinder length="0.1215" radius="0.02225"/>
      </geometry>
    </collision>
    <inertial>
      <mass value="0.88"/>
      <inertia ixx="0.00119147875" ixy="0" ixz="0" iyy="0.00119147875" iyz="0" izz="0.00021782749999999998"/>
    </inertial>
  </link>
  <gazebo reference="wheel2_motor_body_link">
    <material>Gazebo/Gray</material>
  </gazebo>
  <joint name="wheel2_motor_shaft_joint" type="continuous">
    <parent link="wheel2_motor_body_link"/>
    <child link="wheel2_motor_shaft_link"/>
    <origin rpy="0 1.5707963267948966 0" xyz="0 0 0"/>
    <axis xyz="0 0 -1"/>
    <!-- <limit velocity="40.0" effort="3.0" /> -->
    <dynamics damping="0.01" friction="0.0"/>
  </joint>
  <transmission name="wheel2_motor_shaft_trans">
    <type>transmission_interface/SimpleTransmission</type>
    <joint name="wheel2_motor_shaft_joint">
      <hardwareInterface>hardware_interface/EffortJointInterface</hardwareInterface>
    </joint>
    <actuator name="wheel2_motor_shaft_motor">
      <hardwareInterface>hardware_interface/EffortJointInterface</hardwareInterface>
      <mechanicalReduction>1</mechanicalReduction>
    </actuator>
  </transmission>
  <link name="wheel2_motor_shaft_link">
    <visual>
      <geometry>
        <mesh filename="package://mecanumrover_samples/meshes/dae/mecanum_wheel.dae"/>
      </geometry>
      <material name="gray"/>
    </visual>
    <collision>
      <origin rpy="0 0 0" xyz="0 0 0"/>
      <geometry>
        <!-- <cylinder radius="0.048" length="0.04572" /> -->
        <cylinder length="0.04572" radius="0.070"/>
        <!-- <mesh filename="package://mecanumrover_samples/meshes/stl/${mesh}.stl" />  -->
      </geometry>
    </collision>
    <inertial>
      <mass value="0.43525"/>
      <inertia ixx="0.0003265215903" ixy="0" ixz="0" iyy="0.0003265215903" iyz="0" izz="0.0005014080000000001"/>
    </inertial>
  </link>
  <gazebo reference="wheel2_motor_shaft_link">
    <material>Gazebo/White</material>
    <mu1 value="0.0"/>
    <mu2 value="0.0"/>
  </gazebo>
  <joint name="wheel2_barrel0_joint" type="continuous">
    <parent link="wheel2_motor_shaft_link"/>
    <child link="wheel2_barrel0_link"/>
    <origin rpy="0.7853981633974483 0 0.0" xyz="0.0666389 0.0 0"/>
    <axis xyz="0 0 1"/>
    <dynamics damping="0.001" friction="0.0"/>
  </joint>
  <link name="wheel2_barrel0_link">
    <visual>
      <geometry>
        <mesh filename="package://mecanumrover_samples/meshes/dae/mecanum_barrel.dae"/>
      </geometry>
      <material name="black"/>
    </visual>
    <collision>
      <geometry>
        <cylinder length="0.0381" radius="0.00956"/>
      </geometry>
    </collision>
    <inertial>
      <mass value="0.01225"/>
      <inertia ixx="1.7617447750000001e-06" ixy="0" ixz="0" iyy="1.7617447750000001e-06" iyz="0" izz="5.597858000000001e-07"/>
    </inertial>
  </link>
  <gazebo reference="wheel2_barrel0_link">
    <material>Gazebo/Black</material>
    <mu1 value="2.5"/>
    <mu2 value="2.5"/>
    <kp value="50000"/>
    <kd value="100"/>
  </gazebo>
  <joint name="wheel2_barrel1_joint" type="continuous">
    <parent link="wheel2_motor_shaft_link"/>
    <child link="wheel2_barrel1_link"/>
    <origin rpy="0.7853981633974483 0 0.4188790204786391" xyz="0.06087766439729952 0.027104482484263944 0"/>
    <axis xyz="0 0 1"/>
    <dynamics damping="0.001" friction="0.0"/>
  </joint>
  <link name="wheel2_barrel1_link">
    <visual>
      <geometry>
        <mesh filename="package://mecanumrover_samples/meshes/dae/mecanum_barrel.dae"/>
      </geometry>
      <material name="black"/>
    </visual>
    <collision>
      <geometry>
        <cylinder length="0.0381" radius="0.00956"/>
      </geometry>
    </collision>
    <inertial>
      <mass value="0.01225"/>
      <inertia ixx="1.7617447750000001e-06" ixy="0" ixz="0" iyy="1.7617447750000001e-06" iyz="0" izz="5.597858000000001e-07"/>
    </inertial>
  </link>
  <gazebo reference="wheel2_barrel1_link">
    <material>Gazebo/Black</material>
    <mu1 value="2.5"/>
    <mu2 value="2.5"/>
    <kp value="50000"/>
    <kd value="100"/>
  </gazebo>
  <joint name="wheel2_barrel2_joint" type="continuous">
    <parent link="wheel2_motor_shaft_link"/>
    <child link="wheel2_barrel2_link"/>
    <origin rpy="0.7853981633974483 0 0.8377580409572782" xyz="0.04459012756408732 0.04952235371050553 0"/>
    <axis xyz="0 0 1"/>
    <dynamics damping="0.001" friction="0.0"/>
  </joint>
  <link name="wheel2_barrel2_link">
    <visual>
      <geometry>
        <mesh filename="package://mecanumrover_samples/meshes/dae/mecanum_barrel.dae"/>
      </geometry>
      <material name="black"/>
    </visual>
    <collision>
      <geometry>
        <cylinder length="0.0381" radius="0.00956"/>
      </geometry>
    </collision>
    <inertial>
      <mass value="0.01225"/>
      <inertia ixx="1.7617447750000001e-06" ixy="0" ixz="0" iyy="1.7617447750000001e-06" iyz="0" izz="5.597858000000001e-07"/>
    </inertial>
  </link>
  <gazebo reference="wheel2_barrel2_link">
    <material>Gazebo/Black</material>
    <mu1 value="2.5"/>
    <mu2 value="2.5"/>
    <kp value="50000"/>
    <kd value="100"/>
  </gazebo>
  <joint name="wheel2_barrel3_joint" type="continuous">
    <parent link="wheel2_motor_shaft_link"/>
    <child link="wheel2_barrel3_link"/>
    <origin rpy="0.7853981633974483 0 1.2566370614359172" xyz="0.020592552586452685 0.0633773600837411 0"/>
    <axis xyz="0 0 1"/>
    <dynamics damping="0.001" friction="0.0"/>
  </joint>
  <link name="wheel2_barrel3_link">
    <visual>
      <geometry>
        <mesh filename="package://mecanumrover_samples/meshes/dae/mecanum_barrel.dae"/>
      </geometry>
      <material name="black"/>
    </visual>
    <collision>
      <geometry>
        <cylinder length="0.0381" radius="0.00956"/>
      </geometry>
    </collision>
    <inertial>
      <mass value="0.01225"/>
      <inertia ixx="1.7617447750000001e-06" ixy="0" ixz="0" iyy="1.7617447750000001e-06" iyz="0" izz="5.597858000000001e-07"/>
    </inertial>
  </link>
  <gazebo reference="wheel2_barrel3_link">
    <material>Gazebo/Black</material>
    <mu1 value="2.5"/>
    <mu2 value="2.5"/>
    <kp value="50000"/>
    <kd value="100"/>
  </gazebo>
  <joint name="wheel2_barrel4_joint" type="continuous">
    <parent link="wheel2_motor_shaft_link"/>
    <child link="wheel2_barrel4_link"/>
    <origin rpy="0.7853981633974483 0 1.6755160819145565" xyz="-0.006965661810846838 0.06627384513325683 0"/>
    <axis xyz="0 0 1"/>
    <dynamics damping="0.001" friction="0.0"/>
  </joint>
  <link name="wheel2_barrel4_link">
    <visual>
      <geometry>
        <mesh filename="package://mecanumrover_samples/meshes/dae/mecanum_barrel.dae"/>
      </geometry>
      <material name="black"/>
    </visual>
    <collision>
      <geometry>
        <cylinder length="0.0381" radius="0.00956"/>
      </geometry>
    </collision>
    <inertial>
      <mass value="0.01225"/>
      <inertia ixx="1.7617447750000001e-06" ixy="0" ixz="0" iyy="1.7617447750000001e-06" iyz="0" izz="5.597858000000001e-07"/>
    </inertial>
  </link>
  <gazebo reference="wheel2_barrel4_link">
    <material>Gazebo/Black</material>
    <mu1 value="2.5"/>
    <mu2 value="2.5"/>
    <kp value="50000"/>
    <kd value="100"/>
  </gazebo>
  <joint name="wheel2_barrel5_joint" type="continuous">
    <parent link="wheel2_motor_shaft_link"/>
    <child link="wheel2_barrel5_link"/>
    <origin rpy="0.7853981633974483 0 2.0943951023931953" xyz="-0.03331944999999999 0.05771098028025083 0"/>
    <axis xyz="0 0 1"/>
    <dynamics damping="0.001" friction="0.0"/>
  </joint>
  <link name="wheel2_barrel5_link">
    <visual>
      <geometry>
        <mesh filename="package://mecanumrover_samples/meshes/dae/mecanum_barrel.dae"/>
      </geometry>
      <material name="black"/>
    </visual>
    <collision>
      <geometry>
        <cylinder length="0.0381" radius="0.00956"/>
      </geometry>
    </collision>
    <inertial>
      <mass value="0.01225"/>
      <inertia ixx="1.7617447750000001e-06" ixy="0" ixz="0" iyy="1.7617447750000001e-06" iyz="0" izz="5.597858000000001e-07"/>
    </inertial>
  </link>
  <gazebo reference="wheel2_barrel5_link">
    <material>Gazebo/Black</material>
    <mu1 value="2.5"/>
    <mu2 value="2.5"/>
    <kp value="50000"/>
    <kd value="100"/>
  </gazebo>
  <joint name="wheel2_barrel6_joint" type="continuous">
    <parent link="wheel2_motor_shaft_link"/>
    <child link="wheel2_barrel6_link"/>
    <origin rpy="0.7853981633974483 0 2.5132741228718345" xyz="-0.05391200258645268 0.03916936264899289 0"/>
    <axis xyz="0 0 1"/>
    <dynamics damping="0.001" friction="0.0"/>
  </joint>
  <link name="wheel2_barrel6_link">
    <visual>
      <geometry>
        <mesh filename="package://mecanumrover_samples/meshes/dae/mecanum_barrel.dae"/>
      </geometry>
      <material name="black"/>
    </visual>
    <collision>
      <geometry>
        <cylinder length="0.0381" radius="0.00956"/>
      </geometry>
    </collision>
    <inertial>
      <mass value="0.01225"/>
      <inertia ixx="1.7617447750000001e-06" ixy="0" ixz="0" iyy="1.7617447750000001e-06" iyz="0" izz="5.597858000000001e-07"/>
    </inertial>
  </link>
  <gazebo reference="wheel2_barrel6_link">
    <material>Gazebo/Black</material>
    <mu1 value="2.5"/>
    <mu2 value="2.5"/>
    <kp value="50000"/>
    <kd value="100"/>
  </gazebo>
  <joint name="wheel2_barrel7_joint" type="continuous">
    <parent link="wheel2_motor_shaft_link"/>
    <child link="wheel2_barrel7_link"/>
    <origin rpy="0.7853981633974483 0 2.9321531433504737" xyz="-0.06518268015054 0.013855006373235581 0"/>
    <axis xyz="0 0 1"/>
    <dynamics damping="0.001" friction="0.0"/>
  </joint>
  <link name="wheel2_barrel7_link">
    <visual>
      <geometry>
        <mesh filename="package://mecanumrover_samples/meshes/dae/mecanum_barrel.dae"/>
      </geometry>
      <material name="black"/>
    </visual>
    <collision>
      <geometry>
        <cylinder length="0.0381" radius="0.00956"/>
      </geometry>
    </collision>
    <inertial>
      <mass value="0.01225"/>
      <inertia ixx="1.7617447750000001e-06" ixy="0" ixz="0" iyy="1.7617447750000001e-06" iyz="0" izz="5.597858000000001e-07"/>
    </inertial>
  </link>
  <gazebo reference="wheel2_barrel7_link">
    <material>Gazebo/Black</material>
    <mu1 value="2.5"/>
    <mu2 value="2.5"/>
    <kp value="50000"/>
    <kd value="100"/>
  </gazebo>
  <joint name="wheel2_barrel8_joint" type="continuous">
    <parent link="wheel2_motor_shaft_link"/>
    <child link="wheel2_barrel8_link"/>
    <origin rpy="0.7853981633974483 0 3.351032163829113" xyz="-0.06518268015054 -0.013855006373235595 0"/>
    <axis xyz="0 0 1"/>
    <dynamics damping="0.001" friction="0.0"/>
  </joint>
  <link name="wheel2_barrel8_link">
    <visual>
      <geometry>
        <mesh filename="package://mecanumrover_samples/meshes/dae/mecanum_barrel.dae"/>
      </geometry>
      <material name="black"/>
    </visual>
    <collision>
      <geometry>
        <cylinder length="0.0381" radius="0.00956"/>
      </geometry>
    </collision>
    <inertial>
      <mass value="0.01225"/>
      <inertia ixx="1.7617447750000001e-06" ixy="0" ixz="0" iyy="1.7617447750000001e-06" iyz="0" izz="5.597858000000001e-07"/>
    </inertial>
  </link>
  <gazebo reference="wheel2_barrel8_link">
    <material>Gazebo/Black</material>
    <mu1 value="2.5"/>
    <mu2 value="2.5"/>
    <kp value="50000"/>
    <kd value="100"/>
  </gazebo>
  <joint name="wheel2_barrel9_joint" type="continuous">
    <parent link="wheel2_motor_shaft_link"/>
    <child link="wheel2_barrel9_link"/>
    <origin rpy="0.7853981633974483 0 3.7699111843077517" xyz="-0.05391200258645269 -0.03916936264899288 0"/>
    <axis xyz="0 0 1"/>
    <dynamics damping="0.001" friction="0.0"/>
  </joint>
  <link name="wheel2_barrel9_link">
    <visual>
      <geometry>
        <mesh filename="package://mecanumrover_samples/meshes/dae/mecanum_barrel.dae"/>
      </geometry>
      <material name="black"/>
    </visual>
    <collision>
      <geometry>
        <cylinder length="0.0381" radius="0.00956"/>
      </geometry>
    </collision>
    <inertial>
      <mass value="0.01225"/>
      <inertia ixx="1.7617447750000001e-06" ixy="0" ixz="0" iyy="1.7617447750000001e-06" iyz="0" izz="5.597858000000001e-07"/>
    </inertial>
  </link>
  <gazebo reference="wheel2_barrel9_link">
    <material>Gazebo/Black</material>
    <mu1 value="2.5"/>
    <mu2 value="2.5"/>
    <kp value="50000"/>
    <kd value="100"/>
  </gazebo>
  <joint name="wheel2_barrel10_joint" type="continuous">
    <parent link="wheel2_motor_shaft_link"/>
    <child link="wheel2_barrel10_link"/>
    <origin rpy="0.7853981633974483 0 4.1887902047863905" xyz="-0.03331945000000003 -0.05771098028025081 0"/>
    <axis xyz="0 0 1"/>
    <dynamics damping="0.001" friction="0.0"/>
  </joint>
  <link name="wheel2_barrel10_link">
    <visual>
      <geometry>
        <mesh filename="package://mecanumrover_samples/meshes/dae/mecanum_barrel.dae"/>
      </geometry>
      <material name="black"/>
    </visual>
    <collision>
      <geometry>
        <cylinder length="0.0381" radius="0.00956"/>
      </geometry>
    </collision>
    <inertial>
      <mass value="0.01225"/>
      <inertia ixx="1.7617447750000001e-06" ixy="0" ixz="0" iyy="1.7617447750000001e-06" iyz="0" izz="5.597858000000001e-07"/>
    </inertial>
  </link>
  <gazebo reference="wheel2_barrel10_link">
    <material>Gazebo/Black</material>
    <mu1 value="2.5"/>
    <mu2 value="2.5"/>
    <kp value="50000"/>
    <kd value="100"/>
  </gazebo>
  <joint name="wheel2_barrel11_joint" type="continuous">
    <parent link="wheel2_motor_shaft_link"/>
    <child link="wheel2_barrel11_link"/>
    <origin rpy="0.7853981633974483 0 4.60766922526503" xyz="-0.006965661810846825 -0.06627384513325683 0"/>
    <axis xyz="0 0 1"/>
    <dynamics damping="0.001" friction="0.0"/>
  </joint>
  <link name="wheel2_barrel11_link">
    <visual>
      <geometry>
        <mesh filename="package://mecanumrover_samples/meshes/dae/mecanum_barrel.dae"/>
      </geometry>
      <material name="black"/>
    </visual>
    <collision>
      <geometry>
        <cylinder length="0.0381" radius="0.00956"/>
      </geometry>
    </collision>
    <inertial>
      <mass value="0.01225"/>
      <inertia ixx="1.7617447750000001e-06" ixy="0" ixz="0" iyy="1.7617447750000001e-06" iyz="0" izz="5.597858000000001e-07"/>
    </inertial>
  </link>
  <gazebo reference="wheel2_barrel11_link">
    <material>Gazebo/Black</material>
    <mu1 value="2.5"/>
    <mu2 value="2.5"/>
    <kp value="50000"/>
    <kd value="100"/>
  </gazebo>
  <joint name="wheel2_barrel12_joint" type="continuous">
    <parent link="wheel2_motor_shaft_link"/>
    <child link="wheel2_barrel12_link"/>
    <origin rpy="0.7853981633974483 0 5.026548245743669" xyz="0.02059255258645267 -0.06337736008374112 0"/>
    <axis xyz="0 0 1"/>
    <dynamics damping="0.001" friction="0.0"/>
  </joint>
  <link name="wheel2_barrel12_link">
    <visual>
      <geometry>
        <mesh filename="package://mecanumrover_samples/meshes/dae/mecanum_barrel.dae"/>
      </geometry>
      <material name="black"/>
    </visual>
    <collision>
      <geometry>
        <cylinder length="0.0381" radius="0.00956"/>
      </geometry>
    </collision>
    <inertial>
      <mass value="0.01225"/>
      <inertia ixx="1.7617447750000001e-06" ixy="0" ixz="0" iyy="1.7617447750000001e-06" iyz="0" izz="5.597858000000001e-07"/>
    </inertial>
  </link>
  <gazebo reference="wheel2_barrel12_link">
    <material>Gazebo/Black</material>
    <mu1 value="2.5"/>
    <mu2 value="2.5"/>
    <kp value="50000"/>
    <kd value="100"/>
  </gazebo>
  <joint name="wheel2_barrel13_joint" type="continuous">
    <parent link="wheel2_motor_shaft_link"/>
    <child link="wheel2_barrel13_link"/>
    <origin rpy="0.7853981633974483 0 5.445427266222308" xyz="0.04459012756408729 -0.04952235371050555 0"/>
    <axis xyz="0 0 1"/>
    <dynamics damping="0.001" friction="0.0"/>
  </joint>
  <link name="wheel2_barrel13_link">
    <visual>
      <geometry>
        <mesh filename="package://mecanumrover_samples/meshes/dae/mecanum_barrel.dae"/>
      </geometry>
      <material name="black"/>
    </visual>
    <collision>
      <geometry>
        <cylinder length="0.0381" radius="0.00956"/>
      </geometry>
    </collision>
    <inertial>
      <mass value="0.01225"/>
      <inertia ixx="1.7617447750000001e-06" ixy="0" ixz="0" iyy="1.7617447750000001e-06" iyz="0" izz="5.597858000000001e-07"/>
    </inertial>
  </link>
  <gazebo reference="wheel2_barrel13_link">
    <material>Gazebo/Black</material>
    <mu1 value="2.5"/>
    <mu2 value="2.5"/>
    <kp value="50000"/>
    <kd value="100"/>
  </gazebo>
  <joint name="wheel2_barrel14_joint" type="continuous">
    <parent link="wheel2_motor_shaft_link"/>
    <child link="wheel2_barrel14_link"/>
    <origin rpy="0.7853981633974483 0 5.8643062867009474" xyz="0.060877664397299525 -0.02710448248426394 0"/>
    <axis xyz="0 0 1"/>
    <dynamics damping="0.001" friction="0.0"/>
  </joint>
  <link name="wheel2_barrel14_link">
    <visual>
      <geometry>
        <mesh filename="package://mecanumrover_samples/meshes/dae/mecanum_barrel.dae"/>
      </geometry>
      <material name="black"/>
    </visual>
    <collision>
      <geometry>
        <cylinder length="0.0381" radius="0.00956"/>
      </geometry>
    </collision>
    <inertial>
      <mass value="0.01225"/>
      <inertia ixx="1.7617447750000001e-06" ixy="0" ixz="0" iyy="1.7617447750000001e-06" iyz="0" izz="5.597858000000001e-07"/>
    </inertial>
  </link>
  <gazebo reference="wheel2_barrel14_link">
    <material>Gazebo/Black</material>
    <mu1 value="2.5"/>
    <mu2 value="2.5"/>
    <kp value="50000"/>
    <kd value="100"/>
  </gazebo>
  <joint name="wheel3_attach_joint" type="fixed">
    <parent link="base_link"/>
    <child link="wheel3_attach_link"/>
    <origin rpy="0 0 -1.5707963267948966" xyz="-0.115 -0.132 0.075"/>
  </joint>
  <link name="wheel3_attach_link"/>
  <joint name="wheel3_base_joint" type="fixed">
    <parent link="wheel3_attach_link"/>
    <child link="wheel3_base_link"/>
    <origin rpy="0 0 0" xyz="0 0 0"/>
  </joint>
  <link name="wheel3_base_link">
    <inertial>
      <mass value="0.010"/>
      <inertia ixx="0.0001" ixy="0" ixz="0" iyy="0.0001" iyz="0" izz="0.0001"/>
    </inertial>
  </link>
  <joint name="wheel3_sus_joint" type="prismatic">
    <parent link="wheel3_base_link"/>
    <child link="wheel3_sus_link"/>
    <limit effort="100" lower="-0.02" upper="0.02" velocity="1.0"/>
    <axis xyz="0 0 1"/>
    <origin rpy="0 0 0" xyz="0 0 0"/>
    <dynamics damping="0.01"/>
  </joint>
  <transmission name="wheel3_sus_trans">
    <type>transmission_interface/SimpleTransmission</type>
    <joint name="wheel3_sus_joint">
      <hardwareInterface>hardware_interface/EffortJointInterface</hardwareInterface>
    </joint>
    <actuator name="wheel3_sus_motor">
      <hardwareInterface>hardware_interface/EffortJointInterface</hardwareInterface>
      <mechanismReduction>1</mechanismReduction>
    </actuator>
  </transmission>
  <gazebo reference="wheel3_sus_joint">
    <kp>50000</kp>
    <kd>500</kd>
  </gazebo>
  <link name="wheel3_sus_link">
    <inertial>
      <mass value="0.010"/>
      <inertia ixx="0.00001" ixy="0.0" ixz="0.0" iyy="0.00001" iyz="0.0" izz="0.00001"/>
    </inertial>
  </link>
  <joint name="wheel3_motor_joint" type="fixed">
    <parent link="wheel3_sus_link"/>
    <child link="wheel3_motor_body_link"/>
  </joint>
  <link name="wheel3_motor_body_link">
    <visual>
      <origin rpy="0 1.5707963267948966 0" xyz="-0.06075 0 0"/>
      <geometry>
        <cylinder length="0.1215" radius="0.02225"/>
      </geometry>
      <material name="gray"/>
    </visual>
    <collision>
      <origin rpy="0 1.5707963267948966 0" xyz="-0.06075 0 0"/>
      <geometry>
        <cylinder length="0.1215" radius="0.02225"/>
      </geometry>
    </collision>
    <inertial>
      <mass value="0.88"/>
      <inertia ixx="0.00119147875" ixy="0" ixz="0" iyy="0.00119147875" iyz="0" izz="0.00021782749999999998"/>
    </inertial>
  </link>
  <gazebo reference="wheel3_motor_body_link">
    <material>Gazebo/Gray</material>
  </gazebo>
  <joint name="wheel3_motor_shaft_joint" type="continuous">
    <parent link="wheel3_motor_body_link"/>
    <child link="wheel3_motor_shaft_link"/>
    <origin rpy="0 1.5707963267948966 0" xyz="0 0 0"/>
    <axis xyz="0 0 -1"/>
    <!-- <limit velocity="40.0" effort="3.0" /> -->
    <dynamics damping="0.01" friction="0.0"/>
  </joint>
  <transmission name="wheel3_motor_shaft_trans">
    <type>transmission_interface/SimpleTransmission</type>
    <joint name="wheel3_motor_shaft_joint">
      <hardwareInterface>hardware_interface/EffortJointInterface</hardwareInterface>
    </joint>
    <actuator name="wheel3_motor_shaft_motor">
      <hardwareInterface>hardware_interface/EffortJointInterface</hardwareInterface>
      <mechanicalReduction>1</mechanicalReduction>
    </actuator>
  </transmission>
  <link name="wheel3_motor_shaft_link">
    <visual>
      <geometry>
        <mesh filename="package://mecanumrover_samples/meshes/dae/mecanum_wheel_rev.dae"/>
      </geometry>
      <material name="gray"/>
    </visual>
    <collision>
      <origin rpy="0 0 0" xyz="0 0 0"/>
      <geometry>
        <!-- <cylinder radius="0.048" length="0.04572" /> -->
        <cylinder length="0.04572" radius="0.070"/>
        <!-- <mesh filename="package://mecanumrover_samples/meshes/stl/${mesh}.stl" />  -->
      </geometry>
    </collision>
    <inertial>
      <mass value="0.43525"/>
      <inertia ixx="0.0003265215903" ixy="0" ixz="0" iyy="0.0003265215903" iyz="0" izz="0.0005014080000000001"/>
    </inertial>
  </link>
  <gazebo reference="wheel3_motor_shaft_link">
    <material>Gazebo/White</material>
    <mu1 value="0.0"/>
    <mu2 value="0.0"/>
  </gazebo>
  <joint name="wheel3_barrel0_joint" type="continuous">
    <parent link="wheel3_motor_shaft_link"/>
    <child link="wheel3_barrel0_link"/>
    <origin rpy="-0.7853981633974483 0 0.0" xyz="0.0666389 0.0 0"/>
    <axis xyz="0 0 1"/>
    <dynamics damping="0.001" friction="0.0"/>
  </joint>
  <link name="wheel3_barrel0_link">
    <visual>
      <geometry>
        <mesh filename="package://mecanumrover_samples/meshes/dae/mecanum_barrel.dae"/>
      </geometry>
      <material name="black"/>
    </visual>
    <collision>
      <geometry>
        <cylinder length="0.0381" radius="0.00956"/>
      </geometry>
    </collision>
    <inertial>
      <mass value="0.01225"/>
      <inertia ixx="1.7617447750000001e-06" ixy="0" ixz="0" iyy="1.7617447750000001e-06" iyz="0" izz="5.597858000000001e-07"/>
    </inertial>
  </link>
  <gazebo reference="wheel3_barrel0_link">
    <material>Gazebo/Black</material>
    <mu1 value="2.5"/>
    <mu2 value="2.5"/>
    <kp value="50000"/>
    <kd value="100"/>
  </gazebo>
  <joint name="wheel3_barrel1_joint" type="continuous">
    <parent link="wheel3_motor_shaft_link"/>
    <child link="wheel3_barrel1_link"/>
    <origin rpy="-0.7853981633974483 0 0.4188790204786391" xyz="0.06087766439729952 0.027104482484263944 0"/>
    <axis xyz="0 0 1"/>
    <dynamics damping="0.001" friction="0.0"/>
  </joint>
  <link name="wheel3_barrel1_link">
    <visual>
      <geometry>
        <mesh filename="package://mecanumrover_samples/meshes/dae/mecanum_barrel.dae"/>
      </geometry>
      <material name="black"/>
    </visual>
    <collision>
      <geometry>
        <cylinder length="0.0381" radius="0.00956"/>
      </geometry>
    </collision>
    <inertial>
      <mass value="0.01225"/>
      <inertia ixx="1.7617447750000001e-06" ixy="0" ixz="0" iyy="1.7617447750000001e-06" iyz="0" izz="5.597858000000001e-07"/>
    </inertial>
  </link>
  <gazebo reference="wheel3_barrel1_link">
    <material>Gazebo/Black</material>
    <mu1 value="2.5"/>
    <mu2 value="2.5"/>
    <kp value="50000"/>
    <kd value="100"/>
  </gazebo>
  <joint name="wheel3_barrel2_joint" type="continuous">
    <parent link="wheel3_motor_shaft_link"/>
    <child link="wheel3_barrel2_link"/>
    <origin rpy="-0.7853981633974483 0 0.8377580409572782" xyz="0.04459012756408732 0.04952235371050553 0"/>
    <axis xyz="0 0 1"/>
    <dynamics damping="0.001" friction="0.0"/>
  </joint>
  <link name="wheel3_barrel2_link">
    <visual>
      <geometry>
        <mesh filename="package://mecanumrover_samples/meshes/dae/mecanum_barrel.dae"/>
      </geometry>
      <material name="black"/>
    </visual>
    <collision>
      <geometry>
        <cylinder length="0.0381" radius="0.00956"/>
      </geometry>
    </collision>
    <inertial>
      <mass value="0.01225"/>
      <inertia ixx="1.7617447750000001e-06" ixy="0" ixz="0" iyy="1.7617447750000001e-06" iyz="0" izz="5.597858000000001e-07"/>
    </inertial>
  </link>
  <gazebo reference="wheel3_barrel2_link">
    <material>Gazebo/Black</material>
    <mu1 value="2.5"/>
    <mu2 value="2.5"/>
    <kp value="50000"/>
    <kd value="100"/>
  </gazebo>
  <joint name="wheel3_barrel3_joint" type="continuous">
    <parent link="wheel3_motor_shaft_link"/>
    <child link="wheel3_barrel3_link"/>
    <origin rpy="-0.7853981633974483 0 1.2566370614359172" xyz="0.020592552586452685 0.0633773600837411 0"/>
    <axis xyz="0 0 1"/>
    <dynamics damping="0.001" friction="0.0"/>
  </joint>
  <link name="wheel3_barrel3_link">
    <visual>
      <geometry>
        <mesh filename="package://mecanumrover_samples/meshes/dae/mecanum_barrel.dae"/>
      </geometry>
      <material name="black"/>
    </visual>
    <collision>
      <geometry>
        <cylinder length="0.0381" radius="0.00956"/>
      </geometry>
    </collision>
    <inertial>
      <mass value="0.01225"/>
      <inertia ixx="1.7617447750000001e-06" ixy="0" ixz="0" iyy="1.7617447750000001e-06" iyz="0" izz="5.597858000000001e-07"/>
    </inertial>
  </link>
  <gazebo reference="wheel3_barrel3_link">
    <material>Gazebo/Black</material>
    <mu1 value="2.5"/>
    <mu2 value="2.5"/>
    <kp value="50000"/>
    <kd value="100"/>
  </gazebo>
  <joint name="wheel3_barrel4_joint" type="continuous">
    <parent link="wheel3_motor_shaft_link"/>
    <child link="wheel3_barrel4_link"/>
    <origin rpy="-0.7853981633974483 0 1.6755160819145565" xyz="-0.006965661810846838 0.06627384513325683 0"/>
    <axis xyz="0 0 1"/>
    <dynamics damping="0.001" friction="0.0"/>
  </joint>
  <link name="wheel3_barrel4_link">
    <visual>
      <geometry>
        <mesh filename="package://mecanumrover_samples/meshes/dae/mecanum_barrel.dae"/>
      </geometry>
      <material name="black"/>
    </visual>
    <collision>
      <geometry>
        <cylinder length="0.0381" radius="0.00956"/>
      </geometry>
    </collision>
    <inertial>
      <mass value="0.01225"/>
      <inertia ixx="1.7617447750000001e-06" ixy="0" ixz="0" iyy="1.7617447750000001e-06" iyz="0" izz="5.597858000000001e-07"/>
    </inertial>
  </link>
  <gazebo reference="wheel3_barrel4_link">
    <material>Gazebo/Black</material>
    <mu1 value="2.5"/>
    <mu2 value="2.5"/>
    <kp value="50000"/>
    <kd value="100"/>
  </gazebo>
  <joint name="wheel3_barrel5_joint" type="continuous">
    <parent link="wheel3_motor_shaft_link"/>
    <child link="wheel3_barrel5_link"/>
    <origin rpy="-0.7853981633974483 0 2.0943951023931953" xyz="-0.03331944999999999 0.05771098028025083 0"/>
    <axis xyz="0 0 1"/>
    <dynamics damping="0.001" friction="0.0"/>
  </joint>
  <link name="wheel3_barrel5_link">
    <visual>
      <geometry>
        <mesh filename="package://mecanumrover_samples/meshes/dae/mecanum_barrel.dae"/>
      </geometry>
      <material name="black"/>
    </visual>
    <collision>
      <geometry>
        <cylinder length="0.0381" radius="0.00956"/>
      </geometry>
    </collision>
    <inertial>
      <mass value="0.01225"/>
      <inertia ixx="1.7617447750000001e-06" ixy="0" ixz="0" iyy="1.7617447750000001e-06" iyz="0" izz="5.597858000000001e-07"/>
    </inertial>
  </link>
  <gazebo reference="wheel3_barrel5_link">
    <material>Gazebo/Black</material>
    <mu1 value="2.5"/>
    <mu2 value="2.5"/>
    <kp value="50000"/>
    <kd value="100"/>
  </gazebo>
  <joint name="wheel3_barrel6_joint" type="continuous">
    <parent link="wheel3_motor_shaft_link"/>
    <child link="wheel3_barrel6_link"/>
    <origin rpy="-0.7853981633974483 0 2.5132741228718345" xyz="-0.05391200258645268 0.03916936264899289 0"/>
    <axis xyz="0 0 1"/>
    <dynamics damping="0.001" friction="0.0"/>
  </joint>
  <link name="wheel3_barrel6_link">
    <visual>
      <geometry>
        <mesh filename="package://mecanumrover_samples/meshes/dae/mecanum_barrel.dae"/>
      </geometry>
      <material name="black"/>
    </visual>
    <collision>
      <geometry>
        <cylinder length="0.0381" radius="0.00956"/>
      </geometry>
    </collision>
    <inertial>
      <mass value="0.01225"/>
      <inertia ixx="1.7617447750000001e-06" ixy="0" ixz="0" iyy="1.7617447750000001e-06" iyz="0" izz="5.597858000000001e-07"/>
    </inertial>
  </link>
  <gazebo reference="wheel3_barrel6_link">
    <material>Gazebo/Black</material>
    <mu1 value="2.5"/>
    <mu2 value="2.5"/>
    <kp value="50000"/>
    <kd value="100"/>
  </gazebo>
  <joint name="wheel3_barrel7_joint" type="continuous">
    <parent link="wheel3_motor_shaft_link"/>
    <child link="wheel3_barrel7_link"/>
    <origin rpy="-0.7853981633974483 0 2.9321531433504737" xyz="-0.06518268015054 0.013855006373235581 0"/>
    <axis xyz="0 0 1"/>
    <dynamics damping="0.001" friction="0.0"/>
  </joint>
  <link name="wheel3_barrel7_link">
    <visual>
      <geometry>
        <mesh filename="package://mecanumrover_samples/meshes/dae/mecanum_barrel.dae"/>
      </geometry>
      <material name="black"/>
    </visual>
    <collision>
      <geometry>
        <cylinder length="0.0381" radius="0.00956"/>
      </geometry>
    </collision>
    <inertial>
      <mass value="0.01225"/>
      <inertia ixx="1.7617447750000001e-06" ixy="0" ixz="0" iyy="1.7617447750000001e-06" iyz="0" izz="5.597858000000001e-07"/>
    </inertial>
  </link>
  <gazebo reference="wheel3_barrel7_link">
    <material>Gazebo/Black</material>
    <mu1 value="2.5"/>
    <mu2 value="2.5"/>
    <kp value="50000"/>
    <kd value="100"/>
  </gazebo>
  <joint name="wheel3_barrel8_joint" type="continuous">
    <parent link="wheel3_motor_shaft_link"/>
    <child link="wheel3_barrel8_link"/>
    <origin rpy="-0.7853981633974483 0 3.351032163829113" xyz="-0.06518268015054 -0.013855006373235595 0"/>
    <axis xyz="0 0 1"/>
    <dynamics damping="0.001" friction="0.0"/>
  </joint>
  <link name="wheel3_barrel8_link">
    <visual>
      <geometry>
        <mesh filename="package://mecanumrover_samples/meshes/dae/mecanum_barrel.dae"/>
      </geometry>
      <material name="black"/>
    </visual>
    <collision>
      <geometry>
        <cylinder length="0.0381" radius="0.00956"/>
      </geometry>
    </collision>
    <inertial>
      <mass value="0.01225"/>
      <inertia ixx="1.7617447750000001e-06" ixy="0" ixz="0" iyy="1.7617447750000001e-06" iyz="0" izz="5.597858000000001e-07"/>
    </inertial>
  </link>
  <gazebo reference="wheel3_barrel8_link">
    <material>Gazebo/Black</material>
    <mu1 value="2.5"/>
    <mu2 value="2.5"/>
    <kp value="50000"/>
    <kd value="100"/>
  </gazebo>
  <joint name="wheel3_barrel9_joint" type="continuous">
    <parent link="wheel3_motor_shaft_link"/>
    <child link="wheel3_barrel9_link"/>
    <origin rpy="-0.7853981633974483 0 3.7699111843077517" xyz="-0.05391200258645269 -0.03916936264899288 0"/>
    <axis xyz="0 0 1"/>
    <dynamics damping="0.001" friction="0.0"/>
  </joint>
  <link name="wheel3_barrel9_link">
    <visual>
      <geometry>
        <mesh filename="package://mecanumrover_samples/meshes/dae/mecanum_barrel.dae"/>
      </geometry>
      <material name="black"/>
    </visual>
    <collision>
      <geometry>
        <cylinder length="0.0381" radius="0.00956"/>
      </geometry>
    </collision>
    <inertial>
      <mass value="0.01225"/>
      <inertia ixx="1.7617447750000001e-06" ixy="0" ixz="0" iyy="1.7617447750000001e-06" iyz="0" izz="5.597858000000001e-07"/>
    </inertial>
  </link>
  <gazebo reference="wheel3_barrel9_link">
    <material>Gazebo/Black</material>
    <mu1 value="2.5"/>
    <mu2 value="2.5"/>
    <kp value="50000"/>
    <kd value="100"/>
  </gazebo>
  <joint name="wheel3_barrel10_joint" type="continuous">
    <parent link="wheel3_motor_shaft_link"/>
    <child link="wheel3_barrel10_link"/>
    <origin rpy="-0.7853981633974483 0 4.1887902047863905" xyz="-0.03331945000000003 -0.05771098028025081 0"/>
    <axis xyz="0 0 1"/>
    <dynamics damping="0.001" friction="0.0"/>
  </joint>
  <link name="wheel3_barrel10_link">
    <visual>
      <geometry>
        <mesh filename="package://mecanumrover_samples/meshes/dae/mecanum_barrel.dae"/>
      </geometry>
      <material name="black"/>
    </visual>
    <collision>
      <geometry>
        <cylinder length="0.0381" radius="0.00956"/>
      </geometry>
    </collision>
    <inertial>
      <mass value="0.01225"/>
      <inertia ixx="1.7617447750000001e-06" ixy="0" ixz="0" iyy="1.7617447750000001e-06" iyz="0" izz="5.597858000000001e-07"/>
    </inertial>
  </link>
  <gazebo reference="wheel3_barrel10_link">
    <material>Gazebo/Black</material>
    <mu1 value="2.5"/>
    <mu2 value="2.5"/>
    <kp value="50000"/>
    <kd value="100"/>
  </gazebo>
  <joint name="wheel3_barrel11_joint" type="continuous">
    <parent link="wheel3_motor_shaft_link"/>
    <child link="wheel3_barrel11_link"/>
    <origin rpy="-0.7853981633974483 0 4.60766922526503" xyz="-0.006965661810846825 -0.06627384513325683 0"/>
    <axis xyz="0 0 1"/>
    <dynamics damping="0.001" friction="0.0"/>
  </joint>
  <link name="wheel3_barrel11_link">
    <visual>
      <geometry>
        <mesh filename="package://mecanumrover_samples/meshes/dae/mecanum_barrel.dae"/>
      </geometry>
      <material name="black"/>
    </visual>
    <collision>
      <geometry>
        <cylinder length="0.0381" radius="0.00956"/>
      </geometry>
    </collision>
    <inertial>
      <mass value="0.01225"/>
      <inertia ixx="1.7617447750000001e-06" ixy="0" ixz="0" iyy="1.7617447750000001e-06" iyz="0" izz="5.597858000000001e-07"/>
    </inertial>
  </link>
  <gazebo reference="wheel3_barrel11_link">
    <material>Gazebo/Black</material>
    <mu1 value="2.5"/>
    <mu2 value="2.5"/>
    <kp value="50000"/>
    <kd value="100"/>
  </gazebo>
  <joint name="wheel3_barrel12_joint" type="continuous">
    <parent link="wheel3_motor_shaft_link"/>
    <child link="wheel3_barrel12_link"/>
    <origin rpy="-0.7853981633974483 0 5.026548245743669" xyz="0.02059255258645267 -0.06337736008374112 0"/>
    <axis xyz="0 0 1"/>
    <dynamics damping="0.001" friction="0.0"/>
  </joint>
  <link name="wheel3_barrel12_link">
    <visual>
      <geometry>
        <mesh filename="package://mecanumrover_samples/meshes/dae/mecanum_barrel.dae"/>
      </geometry>
      <material name="black"/>
    </visual>
    <collision>
      <geometry>
        <cylinder length="0.0381" radius="0.00956"/>
      </geometry>
    </collision>
    <inertial>
      <mass value="0.01225"/>
      <inertia ixx="1.7617447750000001e-06" ixy="0" ixz="0" iyy="1.7617447750000001e-06" iyz="0" izz="5.597858000000001e-07"/>
    </inertial>
  </link>
  <gazebo reference="wheel3_barrel12_link">
    <material>Gazebo/Black</material>
    <mu1 value="2.5"/>
    <mu2 value="2.5"/>
    <kp value="50000"/>
    <kd value="100"/>
  </gazebo>
  <joint name="wheel3_barrel13_joint" type="continuous">
    <parent link="wheel3_motor_shaft_link"/>
    <child link="wheel3_barrel13_link"/>
    <origin rpy="-0.7853981633974483 0 5.445427266222308" xyz="0.04459012756408729 -0.04952235371050555 0"/>
    <axis xyz="0 0 1"/>
    <dynamics damping="0.001" friction="0.0"/>
  </joint>
  <link name="wheel3_barrel13_link">
    <visual>
      <geometry>
        <mesh filename="package://mecanumrover_samples/meshes/dae/mecanum_barrel.dae"/>
      </geometry>
      <material name="black"/>
    </visual>
    <collision>
      <geometry>
        <cylinder length="0.0381" radius="0.00956"/>
      </geometry>
    </collision>
    <inertial>
      <mass value="0.01225"/>
      <inertia ixx="1.7617447750000001e-06" ixy="0" ixz="0" iyy="1.7617447750000001e-06" iyz="0" izz="5.597858000000001e-07"/>
    </inertial>
  </link>
  <gazebo reference="wheel3_barrel13_link">
    <material>Gazebo/Black</material>
    <mu1 value="2.5"/>
    <mu2 value="2.5"/>
    <kp value="50000"/>
    <kd value="100"/>
  </gazebo>
  <joint name="wheel3_barrel14_joint" type="continuous">
    <parent link="wheel3_motor_shaft_link"/>
    <child link="wheel3_barrel14_link"/>
    <origin rpy="-0.7853981633974483 0 5.8643062867009474" xyz="0.060877664397299525 -0.02710448248426394 0"/>
    <axis xyz="0 0 1"/>
    <dynamics damping="0.001" friction="0.0"/>
  </joint>
  <link name="wheel3_barrel14_link">
    <visual>
      <geometry>
        <mesh filename="package://mecanumrover_samples/meshes/dae/mecanum_barrel.dae"/>
      </geometry>
      <material name="black"/>
    </visual>
    <collision>
      <geometry>
        <cylinder length="0.0381" radius="0.00956"/>
      </geometry>
    </collision>
    <inertial>
      <mass value="0.01225"/>
      <inertia ixx="1.7617447750000001e-06" ixy="0" ixz="0" iyy="1.7617447750000001e-06" iyz="0" izz="5.597858000000001e-07"/>
    </inertial>
  </link>
  <gazebo reference="wheel3_barrel14_link">
    <material>Gazebo/Black</material>
    <mu1 value="2.5"/>
    <mu2 value="2.5"/>
    <kp value="50000"/>
    <kd value="100"/>
  </gazebo>
  <joint name="board_right_joint" type="fixed">
    <parent link="body_link"/>
    <child link="bumper_board_right_link"/>
    <origin rpy="0 0 3.141592653589793" xyz="0.0 0.157 0.0285"/>
  </joint>
  <link name="bumper_board_right_link">
    <visual>
      <geometry>
        <mesh filename="package://mecanumrover_samples/meshes/dae/mecanum_bumper_sidelink.dae"/>
      </geometry>
      <material name="gray"/>
    </visual>
    <collision>
      <geometry>
        <mesh filename="package://mecanumrover_samples/meshes/stl/mecanum_bumper_sidelink.stl"/>
      </geometry>
    </collision>
    <inertial>
      <mass value="0.038"/>
      <inertia ixx="0.00034055221298333327" ixy="0" ixz="0" iyy="0.0003369822266666666" iyz="0" izz="3.6269863166666654e-06"/>
    </inertial>
  </link>
  <gazebo reference="bumper_board_right_link">
    <material>Gazebo/White</material>
  </gazebo>
  <joint name="bumper_baseboard_right_joint" type="fixed">
    <parent link="bumper_board_right_link"/>
    <child link="bumper_baseboard_right_link"/>
    <origin rpy="0 0 0.0" xyz="0.0 -0.024 0.005"/>
  </joint>
  <link name="bumper_baseboard_right_link">
    <visual>
      <geometry>
        <mesh filename="package://mecanumrover_samples/meshes/dae/mecanum_bumper_plate.dae"/>
      </geometry>
      <material name="gray"/>
    </visual>
    <collision>
      <geometry>
        <mesh filename="package://mecanumrover_samples/meshes/stl/mecanum_bumper_plate.stl"/>
      </geometry>
    </collision>
    <inertial>
      <mass value="0.195"/>
      <inertia ixx="0.0011441462500000003" ixy="0" ixz="0" iyy="0.0011010390625" iyz="0" izz="4.8185312500000005e-05"/>
    </inertial>
  </link>
  <gazebo reference="bumper_baseboard_right_link">
    <material>Gazebo/White</material>
  </gazebo>
  <joint name="bumper_right_0_joint" type="prismatic">
    <parent link="bumper_baseboard_right_link"/>
    <child link="bumper_right_0_link"/>
    <origin rpy="0 0 0.4537856055185257" xyz="0.10521 -0.024711 -0.00325"/>
    <limit effort="1" lower="0.0" upper="0.005" velocity="1.0"/>
    <axis xyz="0 1 0"/>
    <origin rpy="0 0 0" xyz="0 0 0"/>
    <dynamics damping="0.01"/>
  </joint>
  <transmission name="bumper_right_0_trans">
    <type>transmission_interface/SimpleTransmission</type>
    <joint name="bumper_right_0_joint">
      <hardwareInterface>hardware_interface/EffortJointInterface</hardwareInterface>
    </joint>
    <actuator name="bumper_right_0_motor">
      <hardwareInterface>hardware_interface/EffortJointInterface</hardwareInterface>
      <mechanismReduction>1</mechanismReduction>
    </actuator>
  </transmission>
  <link name="bumper_right_0_link">
    <visual>
      <geometry>
        <mesh filename="package://mecanumrover_samples/meshes/dae/mecanum_bumper.dae"/>
      </geometry>
      <material name="gray"/>
    </visual>
    <collision>
      <geometry>
        <mesh filename="package://mecanumrover_samples/meshes/stl/mecanum_bumper.stl"/>
      </geometry>
    </collision>
    <inertial>
      <mass value="0.016"/>
      <inertia ixx="1.4630000133333332e-05" ixy="0" ixz="0" iyy="7.944289333333334e-07" iyz="0" izz="1.5007095466666665e-05"/>
    </inertial>
  </link>
  <gazebo reference="bumper_right_0_link">
    <material>Gazebo/White</material>
    <kp value="10000"/>
    <kd value="100"/>
  </gazebo>
  <joint name="bumper_right_1_joint" type="prismatic">
    <parent link="bumper_baseboard_right_link"/>
    <child link="bumper_right_1_link"/>
    <origin rpy="0 0 0.0" xyz="0 -0.049 -0.00325"/>
    <limit effort="1" lower="0.0" upper="0.005" velocity="1.0"/>
    <axis xyz="0 1 0"/>
    <origin rpy="0 0 0" xyz="0 0 0"/>
    <dynamics damping="0.01"/>
  </joint>
  <transmission name="bumper_right_1_trans">
    <type>transmission_interface/SimpleTransmission</type>
    <joint name="bumper_right_1_joint">
      <hardwareInterface>hardware_interface/EffortJointInterface</hardwareInterface>
    </joint>
    <actuator name="bumper_right_1_motor">
      <hardwareInterface>hardware_interface/EffortJointInterface</hardwareInterface>
      <mechanismReduction>1</mechanismReduction>
    </actuator>
  </transmission>
  <link name="bumper_right_1_link">
    <visual>
      <geometry>
        <mesh filename="package://mecanumrover_samples/meshes/dae/mecanum_bumper.dae"/>
      </geometry>
      <material name="gray"/>
    </visual>
    <collision>
      <geometry>
        <mesh filename="package://mecanumrover_samples/meshes/stl/mecanum_bumper.stl"/>
      </geometry>
    </collision>
    <inertial>
      <mass value="0.016"/>
      <inertia ixx="1.4630000133333332e-05" ixy="0" ixz="0" iyy="7.944289333333334e-07" iyz="0" izz="1.5007095466666665e-05"/>
    </inertial>
  </link>
  <gazebo reference="bumper_right_1_link">
    <material>Gazebo/White</material>
    <kp value="10000"/>
    <kd value="100"/>
  </gazebo>
  <joint name="bumper_right_2_joint" type="prismatic">
    <parent link="bumper_baseboard_right_link"/>
    <child link="bumper_right_2_link"/>
    <origin rpy="0 0 -0.4537856055185257" xyz="-0.10521 -0.024711 -0.00325"/>
    <limit effort="1" lower="0.0" upper="0.005" velocity="1.0"/>
    <axis xyz="0 1 0"/>
    <origin rpy="0 0 0" xyz="0 0 0"/>
    <dynamics damping="0.01"/>
  </joint>
  <transmission name="bumper_right_2_trans">
    <type>transmission_interface/SimpleTransmission</type>
    <joint name="bumper_right_2_joint">
      <hardwareInterface>hardware_interface/EffortJointInterface</hardwareInterface>
    </joint>
    <actuator name="bumper_right_2_motor">
      <hardwareInterface>hardware_interface/EffortJointInterface</hardwareInterface>
      <mechanismReduction>1</mechanismReduction>
    </actuator>
  </transmission>
  <link name="bumper_right_2_link">
    <visual>
      <geometry>
        <mesh filename="package://mecanumrover_samples/meshes/dae/mecanum_bumper.dae"/>
      </geometry>
      <material name="gray"/>
    </visual>
    <collision>
      <geometry>
        <mesh filename="package://mecanumrover_samples/meshes/stl/mecanum_bumper.stl"/>
      </geometry>
    </collision>
    <inertial>
      <mass value="0.016"/>
      <inertia ixx="1.4630000133333332e-05" ixy="0" ixz="0" iyy="7.944289333333334e-07" iyz="0" izz="1.5007095466666665e-05"/>
    </inertial>
  </link>
  <gazebo reference="bumper_right_2_link">
    <material>Gazebo/White</material>
    <kp value="10000"/>
    <kd value="100"/>
  </gazebo>
  <joint name="board_left_joint" type="fixed">
    <parent link="body_link"/>
    <child link="bumper_board_left_link"/>
    <origin rpy="0 0 0.0" xyz="0.0 -0.157 0.0285"/>
  </joint>
  <link name="bumper_board_left_link">
    <visual>
      <geometry>
        <mesh filename="package://mecanumrover_samples/meshes/dae/mecanum_bumper_sidelink.dae"/>
      </geometry>
      <material name="gray"/>
    </visual>
    <collision>
      <geometry>
        <mesh filename="package://mecanumrover_samples/meshes/stl/mecanum_bumper_sidelink.stl"/>
      </geometry>
    </collision>
    <inertial>
      <mass value="0.038"/>
      <inertia ixx="0.00034055221298333327" ixy="0" ixz="0" iyy="0.0003369822266666666" iyz="0" izz="3.6269863166666654e-06"/>
    </inertial>
  </link>
  <gazebo reference="bumper_board_left_link">
    <material>Gazebo/White</material>
  </gazebo>
  <joint name="bumper_baseboard_left_joint" type="fixed">
    <parent link="bumper_board_left_link"/>
    <child link="bumper_baseboard_left_link"/>
    <origin rpy="0 0 0.0" xyz="0.0 -0.024 0.005"/>
  </joint>
  <link name="bumper_baseboard_left_link">
    <visual>
      <geometry>
        <mesh filename="package://mecanumrover_samples/meshes/dae/mecanum_bumper_plate.dae"/>
      </geometry>
      <material name="gray"/>
    </visual>
    <collision>
      <geometry>
        <mesh filename="package://mecanumrover_samples/meshes/stl/mecanum_bumper_plate.stl"/>
      </geometry>
    </collision>
    <inertial>
      <mass value="0.195"/>
      <inertia ixx="0.0011441462500000003" ixy="0" ixz="0" iyy="0.0011010390625" iyz="0" izz="4.8185312500000005e-05"/>
    </inertial>
  </link>
  <gazebo reference="bumper_baseboard_left_link">
    <material>Gazebo/White</material>
  </gazebo>
  <joint name="bumper_left_0_joint" type="prismatic">
    <parent link="bumper_baseboard_left_link"/>
    <child link="bumper_left_0_link"/>
    <origin rpy="0 0 0.4537856055185257" xyz="0.10521 -0.024711 -0.00325"/>
    <limit effort="1" lower="0.0" upper="0.005" velocity="1.0"/>
    <axis xyz="0 1 0"/>
    <origin rpy="0 0 0" xyz="0 0 0"/>
    <dynamics damping="0.01"/>
  </joint>
  <transmission name="bumper_left_0_trans">
    <type>transmission_interface/SimpleTransmission</type>
    <joint name="bumper_left_0_joint">
      <hardwareInterface>hardware_interface/EffortJointInterface</hardwareInterface>
    </joint>
    <actuator name="bumper_left_0_motor">
      <hardwareInterface>hardware_interface/EffortJointInterface</hardwareInterface>
      <mechanismReduction>1</mechanismReduction>
    </actuator>
  </transmission>
  <link name="bumper_left_0_link">
    <visual>
      <geometry>
        <mesh filename="package://mecanumrover_samples/meshes/dae/mecanum_bumper.dae"/>
      </geometry>
      <material name="gray"/>
    </visual>
    <collision>
      <geometry>
        <mesh filename="package://mecanumrover_samples/meshes/stl/mecanum_bumper.stl"/>
      </geometry>
    </collision>
    <inertial>
      <mass value="0.016"/>
      <inertia ixx="1.4630000133333332e-05" ixy="0" ixz="0" iyy="7.944289333333334e-07" iyz="0" izz="1.5007095466666665e-05"/>
    </inertial>
  </link>
  <gazebo reference="bumper_left_0_link">
    <material>Gazebo/White</material>
    <kp value="10000"/>
    <kd value="100"/>
  </gazebo>
  <joint name="bumper_left_1_joint" type="prismatic">
    <parent link="bumper_baseboard_left_link"/>
    <child link="bumper_left_1_link"/>
    <origin rpy="0 0 0.0" xyz="0 -0.049 -0.00325"/>
    <limit effort="1" lower="0.0" upper="0.005" velocity="1.0"/>
    <axis xyz="0 1 0"/>
    <origin rpy="0 0 0" xyz="0 0 0"/>
    <dynamics damping="0.01"/>
  </joint>
  <transmission name="bumper_left_1_trans">
    <type>transmission_interface/SimpleTransmission</type>
    <joint name="bumper_left_1_joint">
      <hardwareInterface>hardware_interface/EffortJointInterface</hardwareInterface>
    </joint>
    <actuator name="bumper_left_1_motor">
      <hardwareInterface>hardware_interface/EffortJointInterface</hardwareInterface>
      <mechanismReduction>1</mechanismReduction>
    </actuator>
  </transmission>
  <link name="bumper_left_1_link">
    <visual>
      <geometry>
        <mesh filename="package://mecanumrover_samples/meshes/dae/mecanum_bumper.dae"/>
      </geometry>
      <material name="gray"/>
    </visual>
    <collision>
      <geometry>
        <mesh filename="package://mecanumrover_samples/meshes/stl/mecanum_bumper.stl"/>
      </geometry>
    </collision>
    <inertial>
      <mass value="0.016"/>
      <inertia ixx="1.4630000133333332e-05" ixy="0" ixz="0" iyy="7.944289333333334e-07" iyz="0" izz="1.5007095466666665e-05"/>
    </inertial>
  </link>
  <gazebo reference="bumper_left_1_link">
    <material>Gazebo/White</material>
    <kp value="10000"/>
    <kd value="100"/>
  </gazebo>
  <joint name="bumper_left_2_joint" type="prismatic">
    <parent link="bumper_baseboard_left_link"/>
    <child link="bumper_left_2_link"/>
    <origin rpy="0 0 -0.4537856055185257" xyz="-0.10521 -0.024711 -0.00325"/>
    <limit effort="1" lower="0.0" upper="0.005" velocity="1.0"/>
    <axis xyz="0 1 0"/>
    <origin rpy="0 0 0" xyz="0 0 0"/>
    <dynamics damping="0.01"/>
  </joint>
  <transmission name="bumper_left_2_trans">
    <type>transmission_interface/SimpleTransmission</type>
    <joint name="bumper_left_2_joint">
      <hardwareInterface>hardware_interface/EffortJointInterface</hardwareInterface>
    </joint>
    <actuator name="bumper_left_2_motor">
      <hardwareInterface>hardware_interface/EffortJointInterface</hardwareInterface>
      <mechanismReduction>1</mechanismReduction>
    </actuator>
  </transmission>
  <link name="bumper_left_2_link">
    <visual>
      <geometry>
        <mesh filename="package://mecanumrover_samples/meshes/dae/mecanum_bumper.dae"/>
      </geometry>
      <material name="gray"/>
    </visual>
    <collision>
      <geometry>
        <mesh filename="package://mecanumrover_samples/meshes/stl/mecanum_bumper.stl"/>
      </geometry>
    </collision>
    <inertial>
      <mass value="0.016"/>
      <inertia ixx="1.4630000133333332e-05" ixy="0" ixz="0" iyy="7.944289333333334e-07" iyz="0" izz="1.5007095466666665e-05"/>
    </inertial>
  </link>
  <gazebo reference="bumper_left_2_link">
    <material>Gazebo/White</material>
    <kp value="10000"/>
    <kd value="100"/>
  </gazebo>
  <joint name="bumper_baseboard_front_joint" type="fixed">
    <parent link="body_link"/>
    <child link="bumper_baseboard_front_link"/>
    <origin rpy="0 0 1.5707963267948966" xyz="0.196 0 0.0365"/>
  </joint>
  <link name="bumper_baseboard_front_link">
    <visual>
      <geometry>
        <mesh filename="package://mecanumrover_samples/meshes/dae/mecanum_bumper_plate.dae"/>
      </geometry>
      <material name="gray"/>
    </visual>
    <collision>
      <geometry>
        <mesh filename="package://mecanumrover_samples/meshes/stl/mecanum_bumper_plate.stl"/>
      </geometry>
    </collision>
    <inertial>
      <mass value="0.195"/>
      <inertia ixx="0.0011441462500000003" ixy="0" ixz="0" iyy="0.0011010390625" iyz="0" izz="4.8185312500000005e-05"/>
    </inertial>
  </link>
  <gazebo reference="bumper_baseboard_front_link">
    <material>Gazebo/White</material>
  </gazebo>
  <joint name="bumper_front_0_joint" type="prismatic">
    <parent link="bumper_baseboard_front_link"/>
    <child link="bumper_front_0_link"/>
    <origin rpy="0 0 0.4537856055185257" xyz="0.10521 -0.024711 -0.00325"/>
    <limit effort="1" lower="0.0" upper="0.005" velocity="1.0"/>
    <axis xyz="0 1 0"/>
    <origin rpy="0 0 0" xyz="0 0 0"/>
    <dynamics damping="0.01"/>
  </joint>
  <transmission name="bumper_front_0_trans">
    <type>transmission_interface/SimpleTransmission</type>
    <joint name="bumper_front_0_joint">
      <hardwareInterface>hardware_interface/EffortJointInterface</hardwareInterface>
    </joint>
    <actuator name="bumper_front_0_motor">
      <hardwareInterface>hardware_interface/EffortJointInterface</hardwareInterface>
      <mechanismReduction>1</mechanismReduction>
    </actuator>
  </transmission>
  <link name="bumper_front_0_link">
    <visual>
      <geometry>
        <mesh filename="package://mecanumrover_samples/meshes/dae/mecanum_bumper.dae"/>
      </geometry>
      <material name="gray"/>
    </visual>
    <collision>
      <geometry>
        <mesh filename="package://mecanumrover_samples/meshes/stl/mecanum_bumper.stl"/>
      </geometry>
    </collision>
    <inertial>
      <mass value="0.016"/>
      <inertia ixx="1.4630000133333332e-05" ixy="0" ixz="0" iyy="7.944289333333334e-07" iyz="0" izz="1.5007095466666665e-05"/>
    </inertial>
  </link>
  <gazebo reference="bumper_front_0_link">
    <material>Gazebo/White</material>
    <kp value="10000"/>
    <kd value="100"/>
  </gazebo>
  <joint name="bumper_front_1_joint" type="prismatic">
    <parent link="bumper_baseboard_front_link"/>
    <child link="bumper_front_1_link"/>
    <origin rpy="0 0 0.0" xyz="0 -0.049 -0.00325"/>
    <limit effort="1" lower="0.0" upper="0.005" velocity="1.0"/>
    <axis xyz="0 1 0"/>
    <origin rpy="0 0 0" xyz="0 0 0"/>
    <dynamics damping="0.01"/>
  </joint>
  <transmission name="bumper_front_1_trans">
    <type>transmission_interface/SimpleTransmission</type>
    <joint name="bumper_front_1_joint">
      <hardwareInterface>hardware_interface/EffortJointInterface</hardwareInterface>
    </joint>
    <actuator name="bumper_front_1_motor">
      <hardwareInterface>hardware_interface/EffortJointInterface</hardwareInterface>
      <mechanismReduction>1</mechanismReduction>
    </actuator>
  </transmission>
  <link name="bumper_front_1_link">
    <visual>
      <geometry>
        <mesh filename="package://mecanumrover_samples/meshes/dae/mecanum_bumper.dae"/>
      </geometry>
      <material name="gray"/>
    </visual>
    <collision>
      <geometry>
        <mesh filename="package://mecanumrover_samples/meshes/stl/mecanum_bumper.stl"/>
      </geometry>
    </collision>
    <inertial>
      <mass value="0.016"/>
      <inertia ixx="1.4630000133333332e-05" ixy="0" ixz="0" iyy="7.944289333333334e-07" iyz="0" izz="1.5007095466666665e-05"/>
    </inertial>
  </link>
  <gazebo reference="bumper_front_1_link">
    <material>Gazebo/White</material>
    <kp value="10000"/>
    <kd value="100"/>
  </gazebo>
  <joint name="bumper_front_2_joint" type="prismatic">
    <parent link="bumper_baseboard_front_link"/>
    <child link="bumper_front_2_link"/>
    <origin rpy="0 0 -0.4537856055185257" xyz="-0.10521 -0.024711 -0.00325"/>
    <limit effort="1" lower="0.0" upper="0.005" velocity="1.0"/>
    <axis xyz="0 1 0"/>
    <origin rpy="0 0 0" xyz="0 0 0"/>
    <dynamics damping="0.01"/>
  </joint>
  <transmission name="bumper_front_2_trans">
    <type>transmission_interface/SimpleTransmission</type>
    <joint name="bumper_front_2_joint">
      <hardwareInterface>hardware_interface/EffortJointInterface</hardwareInterface>
    </joint>
    <actuator name="bumper_front_2_motor">
      <hardwareInterface>hardware_interface/EffortJointInterface</hardwareInterface>
      <mechanismReduction>1</mechanismReduction>
    </actuator>
  </transmission>
  <link name="bumper_front_2_link">
    <visual>
      <geometry>
        <mesh filename="package://mecanumrover_samples/meshes/dae/mecanum_bumper.dae"/>
      </geometry>
      <material name="gray"/>
    </visual>
    <collision>
      <geometry>
        <mesh filename="package://mecanumrover_samples/meshes/stl/mecanum_bumper.stl"/>
      </geometry>
    </collision>
    <inertial>
      <mass value="0.016"/>
      <inertia ixx="1.4630000133333332e-05" ixy="0" ixz="0" iyy="7.944289333333334e-07" iyz="0" izz="1.5007095466666665e-05"/>
    </inertial>
  </link>
  <gazebo reference="bumper_front_2_link">
    <material>Gazebo/White</material>
    <kp value="10000"/>
    <kd value="100"/>
  </gazebo>
  <joint name="bumper_baseboard_back_joint" type="fixed">
    <parent link="body_link"/>
    <child link="bumper_baseboard_back_link"/>
    <origin rpy="0 0 -1.5707963267948966" xyz="-0.196 0 0.0365"/>
  </joint>
  <link name="bumper_baseboard_back_link">
    <visual>
      <geometry>
        <mesh filename="package://mecanumrover_samples/meshes/dae/mecanum_bumper_plate.dae"/>
      </geometry>
      <material name="gray"/>
    </visual>
    <collision>
      <geometry>
        <mesh filename="package://mecanumrover_samples/meshes/stl/mecanum_bumper_plate.stl"/>
      </geometry>
    </collision>
    <inertial>
      <mass value="0.195"/>
      <inertia ixx="0.0011441462500000003" ixy="0" ixz="0" iyy="0.0011010390625" iyz="0" izz="4.8185312500000005e-05"/>
    </inertial>
  </link>
  <gazebo reference="bumper_baseboard_back_link">
    <material>Gazebo/White</material>
  </gazebo>
  <joint name="bumper_back_0_joint" type="prismatic">
    <parent link="bumper_baseboard_back_link"/>
    <child link="bumper_back_0_link"/>
    <origin rpy="0 0 0.4537856055185257" xyz="0.10521 -0.024711 -0.00325"/>
    <limit effort="1" lower="0.0" upper="0.005" velocity="1.0"/>
    <axis xyz="0 1 0"/>
    <origin rpy="0 0 0" xyz="0 0 0"/>
    <dynamics damping="0.01"/>
  </joint>
  <transmission name="bumper_back_0_trans">
    <type>transmission_interface/SimpleTransmission</type>
    <joint name="bumper_back_0_joint">
      <hardwareInterface>hardware_interface/EffortJointInterface</hardwareInterface>
    </joint>
    <actuator name="bumper_back_0_motor">
      <hardwareInterface>hardware_interface/EffortJointInterface</hardwareInterface>
      <mechanismReduction>1</mechanismReduction>
    </actuator>
  </transmission>
  <link name="bumper_back_0_link">
    <visual>
      <geometry>
        <mesh filename="package://mecanumrover_samples/meshes/dae/mecanum_bumper.dae"/>
      </geometry>
      <material name="gray"/>
    </visual>
    <collision>
      <geometry>
        <mesh filename="package://mecanumrover_samples/meshes/stl/mecanum_bumper.stl"/>
      </geometry>
    </collision>
    <inertial>
      <mass value="0.016"/>
      <inertia ixx="1.4630000133333332e-05" ixy="0" ixz="0" iyy="7.944289333333334e-07" iyz="0" izz="1.5007095466666665e-05"/>
    </inertial>
  </link>
  <gazebo reference="bumper_back_0_link">
    <material>Gazebo/White</material>
    <kp value="10000"/>
    <kd value="100"/>
  </gazebo>
  <joint name="bumper_back_1_joint" type="prismatic">
    <parent link="bumper_baseboard_back_link"/>
    <child link="bumper_back_1_link"/>
    <origin rpy="0 0 0.0" xyz="0 -0.049 -0.00325"/>
    <limit effort="1" lower="0.0" upper="0.005" velocity="1.0"/>
    <axis xyz="0 1 0"/>
    <origin rpy="0 0 0" xyz="0 0 0"/>
    <dynamics damping="0.01"/>
  </joint>
  <transmission name="bumper_back_1_trans">
    <type>transmission_interface/SimpleTransmission</type>
    <joint name="bumper_back_1_joint">
      <hardwareInterface>hardware_interface/EffortJointInterface</hardwareInterface>
    </joint>
    <actuator name="bumper_back_1_motor">
      <hardwareInterface>hardware_interface/EffortJointInterface</hardwareInterface>
      <mechanismReduction>1</mechanismReduction>
    </actuator>
  </transmission>
  <link name="bumper_back_1_link">
    <visual>
      <geometry>
        <mesh filename="package://mecanumrover_samples/meshes/dae/mecanum_bumper.dae"/>
      </geometry>
      <material name="gray"/>
    </visual>
    <collision>
      <geometry>
        <mesh filename="package://mecanumrover_samples/meshes/stl/mecanum_bumper.stl"/>
      </geometry>
    </collision>
    <inertial>
      <mass value="0.016"/>
      <inertia ixx="1.4630000133333332e-05" ixy="0" ixz="0" iyy="7.944289333333334e-07" iyz="0" izz="1.5007095466666665e-05"/>
    </inertial>
  </link>
  <gazebo reference="bumper_back_1_link">
    <material>Gazebo/White</material>
    <kp value="10000"/>
    <kd value="100"/>
  </gazebo>
  <joint name="bumper_back_2_joint" type="prismatic">
    <parent link="bumper_baseboard_back_link"/>
    <child link="bumper_back_2_link"/>
    <origin rpy="0 0 -0.4537856055185257" xyz="-0.10521 -0.024711 -0.00325"/>
    <limit effort="1" lower="0.0" upper="0.005" velocity="1.0"/>
    <axis xyz="0 1 0"/>
    <origin rpy="0 0 0" xyz="0 0 0"/>
    <dynamics damping="0.01"/>
  </joint>
  <transmission name="bumper_back_2_trans">
    <type>transmission_interface/SimpleTransmission</type>
    <joint name="bumper_back_2_joint">
      <hardwareInterface>hardware_interface/EffortJointInterface</hardwareInterface>
    </joint>
    <actuator name="bumper_back_2_motor">
      <hardwareInterface>hardware_interface/EffortJointInterface</hardwareInterface>
      <mechanismReduction>1</mechanismReduction>
    </actuator>
  </transmission>
  <link name="bumper_back_2_link">
    <visual>
      <geometry>
        <mesh filename="package://mecanumrover_samples/meshes/dae/mecanum_bumper.dae"/>
      </geometry>
      <material name="gray"/>
    </visual>
    <collision>
      <geometry>
        <mesh filename="package://mecanumrover_samples/meshes/stl/mecanum_bumper.stl"/>
      </geometry>
    </collision>
    <inertial>
      <mass value="0.016"/>
      <inertia ixx="1.4630000133333332e-05" ixy="0" ixz="0" iyy="7.944289333333334e-07" iyz="0" izz="1.5007095466666665e-05"/>
    </inertial>
  </link>
  <gazebo reference="bumper_back_2_link">
    <material>Gazebo/White</material>
    <kp value="10000"/>
    <kd value="100"/>
  </gazebo>
  <joint name="board_front_joint" type="fixed">
    <parent link="body_link"/>
    <child link="board_front_link"/>
    <origin rpy="0 0 0.0" xyz="0.157 0 0.1585"/>
  </joint>
  <link name="board_front_link">
    <visual>
      <geometry>
        <mesh filename="package://mecanumrover_samples/meshes/dae/mecanum_optionattachboard.dae"/>
      </geometry>
      <material name="gray"/>
    </visual>
    <collision>
      <geometry>
        <mesh filename="package://mecanumrover_samples/meshes/stl/mecanum_optionattachboard.stl"/>
      </geometry>
    </collision>
    <inertial>
      <mass value="0.078"/>
      <inertia ixx="0.000144509625" ixy="0" ixz="0" iyy="5.096812499999999e-05" iyz="0" izz="9.36585e-05"/>
    </inertial>
  </link>
  <gazebo reference="board_front_link">
    <material>Gazebo/White</material>
  </gazebo>
  <joint name="board_back_joint" type="fixed">
    <parent link="body_link"/>
    <child link="board_back_link"/>
    <origin rpy="0 0 3.141592653589793" xyz="-0.157 0 0.1585"/>
  </joint>
  <link name="board_back_link">
    <visual>
      <geometry>
        <mesh filename="package://mecanumrover_samples/meshes/dae/mecanum_optionattachboard.dae"/>
      </geometry>
      <material name="gray"/>
    </visual>
    <collision>
      <geometry>
        <mesh filename="package://mecanumrover_samples/meshes/stl/mecanum_optionattachboard.stl"/>
      </geometry>
    </collision>
    <inertial>
      <mass value="0.078"/>
      <inertia ixx="0.000144509625" ixy="0" ixz="0" iyy="5.096812499999999e-05" iyz="0" izz="9.36585e-05"/>
    </inertial>
  </link>
  <gazebo reference="board_back_link">
    <material>Gazebo/White</material>
  </gazebo>
  <!-- LiDAR  -->
  <joint name="lidar_joint" type="fixed">
    <parent link="board_front_link"/>
    <child link="lidar_link"/>
    <!-- attach upper side -->
    <!--    <origin xyz="0.042 0 0.0570" rpy="0 0 0"/> -->
    <!-- attach lower side -->
    <origin rpy="3.141592653589793 0 0" xyz="0.042 0 -0.0570"/>
  </joint>
  <link name="lidar_link">
      <geometry>
        <mesh filename="package://velodyne_description/meshes/VLP16_base_1.dae"/>
      </geometry>
    </visual>
    <visual>
      <geometry>
        <mesh filename="package://velodyne_description/meshes/VLP16_base_2.dae"/>
      </geometry>
    </visual>
    <collision>
      <origin rpy="0 0 0" xyz="0 0 0.03585"/>
      <geometry>
        <cylinder radius="0.0516" length="0.0717"/>
      </geometry>
    </collision>
    <inertial>
      <mass value="0.83"/>
      <origin xyz="0 0 0.03585"/>
      <inertia ixx="0.00091" ixy="0" ixz="0" iyy="0.00091" iyz="0" izz="0.001105"/>
    </inertial>
  </link>
  <gazebo reference="lidar_link">
    <material>Gazebo/Black</material>
    <sensor name="lidar_sensor" type="ray">
      <pose>0 0 0 0 0 0</pose>
      <visualize>true</visualize>
      <update_rate>40</update_rate>
      <ray>
        <scan>
          <horizontal>
            <samples>1000</samples>
            <resolution>1</resolution>
            <min_angle>-1.57</min_angle>
            <max_angle>1.57</max_angle>
          </horizontal>
        </scan>
        <range>
          <min>0.06</min>
          <max>4.0</max>
          <resolution>0.001</resolution>
        </range>
        <noise>
          <type>gaussian</type>
          <mean>0.0</mean>
          <stddev>0.03</stddev>
        </noise>
      </ray>
      <plugin filename="libgazebo_ros_laser.so" name="gazebo_ros_lrf_controller">
        <topicName>/scan</topicName>
        <frameName>lidar_link</frameName>
      </plugin>
    </sensor>
  </gazebo>
  <!-- emergency button  -->
  <joint name="button_joint" type="fixed">
    <parent link="board_back_link"/>
    <child link="button_link"/>
    <origin rpy="0 0 0" xyz="0.032 0 -0.0072"/>
  </joint>
  <link name="button_link">
    <visual>
      <geometry>
        <mesh filename="package://mecanumrover_samples/meshes/dae/mecanum_button.dae"/>
      </geometry>
      <material name="red"/>
    </visual>
    <collision>
      <geometry>
        <mesh filename="package://mecanumrover_samples/meshes/stl/mecanum_button.stl"/>
      </geometry>
    </collision>
    <inertial>
      <mass value="0.48"/>
      <inertia ixx="7.057439999999999e-05" ixy="0" ixz="0" iyy="0.003697244799999999" iyz="0" izz="0.003698670399999999"/>
    </inertial>
  </link>
  <gazebo reference="button_link">
    <material>Gazebo/Red</material>
  </gazebo>
  <!-- Wyreless charger  -->
  <!-- attachiment  -->
  <!--
  <joint name="charger_attach_joint" type="fixed">
    <parent link="board_front_link"/>
    <child  link="charger_attach_link"/>
    <origin xyz="0.06 0 -0.0015" rpy="0 0 0"/>
  </joint>
  <link name="charger_attach_link">
    <visual>
      <geometry>
          <mesh filename="package://mecanumrover_samples/meshes/dae/mecanum_charger_attach.dae" />
      </geometry>
      <material name="gray"/>
    </visual>
    <collision>
      <geometry>
          <mesh filename="package://mecanumrover_samples/meshes/stl/mecanum_charger_attach.stl" />
      </geometry>
    </collision>
    <inertial>
        <xacro:box_inertial mass="0.222" height="0.08" width="0.078" depth="0.026" />
    </inertial>  

  </link>
  <gazebo reference="charger_attach_link">
    <material>Gazebo/White</material>
  </gazebo>
-->
  <!-- wyreless charger  -->
  <!--
  <joint name="charger_joint" type="prismatic">
    <parent link="charger_attach_link"/>
    <child  link="charger_link"/>
    <origin xyz="0.0645 0 -0.03" rpy="0 0 0"/>

    <limit lower="-0.007" upper="0.0" effort="1" velocity="1.0" />
    <axis xyz="1 0 0"/>
    <origin xyz="0 0 0" rpy="0 0 0"/>
    <dynamics damping="0.01"/>

  </joint>
  <transmission name="charger_trans">
    <type>transmission_interface/SimpleTransmission</type>
    <joint name="charger_joint">
        <hardwareInterface>hardware_interface/EffortJointInterface</hardwareInterface>
    </joint>
    <actuator name="charger_motor">
      <hardwareInterface>hardware_interface/EffortJointInterface</hardwareInterface>
      <mechanismReduction>1</mechanismReduction>
    </actuator>
  </transmission>

  <link name="charger_link">
    <visual>
      <geometry>
          <mesh filename="package://mecanumrover_samples/meshes/dae/mecanum_charger.dae" />
      </geometry>
      <material name="black"/>
    </visual>
    <collision>
      <geometry>
          <mesh filename="package://mecanumrover_samples/meshes/stl/mecanum_charger.stl" />
      </geometry>
    </collision>
    <inertial>
        <xacro:box_inertial mass="1.678" height="0.11" width="0.16" depth="0.0781" />
    </inertial>  

  </link>
  <gazebo reference="charger_link">
    <material>Gazebo/Black</material>
    <mu1 value="2.5" />
    <mu2 value="2.5" />
    <kp value="50000" />
    <kd value="100" />
  </gazebo>
-->
  <!-- NUC PC  -->
  <!-- option attach board  -->
  <joint name="board_center_joint" type="fixed">
    <parent link="body_link"/>
    <child link="board_center_link"/>
    <origin rpy="0 0 0" xyz="0.0 0 0.1665"/>
  </joint>
  <link name="board_center_link">
    <visual>
      <geometry>
        <mesh filename="package://mecanumrover_samples/meshes/dae/mecanum_nuc_board.dae"/>
      </geometry>
      <material name="gray"/>
    </visual>
    <collision>
      <geometry>
        <mesh filename="package://mecanumrover_samples/meshes/stl/mecanum_nuc_board.stl"/>
      </geometry>
    </collision>
    <inertial>
      <mass value="0.16"/>
      <inertia ixx="0.0010923333333333334" ixy="0" ixz="0" iyy="0.00012045333333333334" iyz="0" izz="0.00097212"/>
    </inertial>
  </link>
  <gazebo reference="board_center_link">
    <material>Gazebo/White</material>
  </gazebo>
  <!-- NUC  -->
  <joint name="nuc_joint" type="fixed">
    <parent link="board_center_link"/>
    <child link="nuc_link"/>
    <origin rpy="0 0 0" xyz="0.0 0 0.019"/>
  </joint>
  <link name="nuc_link">
    <visual>
      <geometry>
        <mesh filename="package://mecanumrover_samples/meshes/dae/mecanum_nuc.dae"/>
      </geometry>
      <material name="black"/>
    </visual>
    <collision>
      <geometry>
        <mesh filename="package://mecanumrover_samples/meshes/stl/mecanum_nuc.stl"/>
      </geometry>
    </collision>
    <inertial>
      <mass value="1.18"/>
      <inertia ixx="0.0025795783333333335" ixy="0" ixz="0" iyy="0.0013553322666666667" iyz="0" izz="0.0014679239333333335"/>
    </inertial>
  </link>
  <gazebo reference="nuc_link">
    <material>Gazebo/Black</material>
  </gazebo>
  <gazebo>
    <plugin filename="libgazebo_ros_control.so" name="gazebo_ros_control">
      <robotNamespace>/vmecanumrover</robotNamespace>
      <robotSimType>gazebo_ros_control/DefaultRobotHWSim</robotSimType>
      <legacyModeNS>true</legacyModeNS>
      <odometryFrame>map</odometryFrame>
    </plugin>
  </gazebo>
</robot>

